  {"type":"subscriptions","channels":[{"name":"full","product_ids":["BTC-USD","ETH-USD"]},{"name":"heartbeat","product_ids":["BTC-USD","ETH-USD"]}]}

  // metrics
  // txn-type per second
  // txn-type volume; peak; low
  //


  {"type":"open","side":"buy","price":"224.35000000","order_id":"6714570b-5cb1-4a72-9013-f8c66e135508","remaining_size":"0.01300000","product_id":"ETH-USD","sequence":7147163717,"time":"2019-08-08T10:10:35.157000Z"}
  
  {"type":"received","order_id":"a475c41f-a70d-4cc1-9fec-6487d7ce43ed","order_type":"limit","size":"4.56500000","price":"11836.25000000","side":"sell","client_oid":"8ce7b3d4-94aa-4932-81aa-984c86387c04","product_id":"BTC-USD","sequence":10477649848,"time":"2019-08-08T10:10:35.166000Z"}
  {"type":"open","side":"sell","price":"11836.25000000","order_id":"a475c41f-a70d-4cc1-9fec-6487d7ce43ed","remaining_size":"4.56500000","product_id":"BTC-USD","sequence":10477649849,"time":"2019-08-08T10:10:35.166000Z"}
  
  // txn type-side-reason
  // txn type-side      
  // * received.buy
  // * open.sell
  // * open.buy
  // * done.sell.cancelled.product_id
  // * price  
  //      
  {"type":"done","side":"sell","order_id":"ed622fed-7568-4769-b472-a86258e94c84","reason":"canceled","product_id":"BTC-USD","price":"11836.27000000","remaining_size":"0.75000000","sequence":10477649850,"time":"2019-08-08T10:10:35.170000Z"}
  {"type":"done","side":"buy","order_id":"e3f57a96-9254-4336-bd40-eb9271d3b35e","reason":"canceled","product_id":"ETH-USD","price":"224.60000000","remaining_size":"12.50000000","sequence":7147163718,"time":"2019-08-08T10:10:35.172000Z"}

  {"type":"received","order_id":"3f00d4bb-a222-4767-9430-e58fe2aad5d7","order_type":"limit","size":"0.75000000","price":"11836.24000000","side":"sell","client_oid":"78dc33c2-b3c6-4aa3-a483-ae7918a4f149","product_id":"BTC-USD","sequence":10477649851,"time":"2019-08-08T10:10:35.178000Z"}
  {"type":"open","side":"sell","price":"11836.24000000","order_id":"3f00d4bb-a222-4767-9430-e58fe2aad5d7","remaining_size":"0.75000000","product_id":"BTC-USD","sequence":10477649852,"time":"2019-08-08T10:10:35.178000Z"}

  {"type":"done","side":"sell","order_id":"a475c41f-a70d-4cc1-9fec-6487d7ce43ed","reason":"canceled","product_id":"BTC-USD","price":"11836.25000000","remaining_size":"4.56500000","sequence":10477649853,"time":"2019-08-08T10:10:35.182000Z"}
  {"type":"received","order_id":"07aadcfa-0b44-474d-819b-a7de4d871f78","order_type":"limit","size":"2.10700000","price":"11843.44000000","side":"sell","client_oid":"def3a7cb-4baf-498f-965d-1652af1ae2a5","product_id":"BTC-USD","sequence":10477649854,"time":"2019-08-08T10:10:35.205000Z"}
  {"type":"open","side":"sell","price":"11843.44000000","order_id":"07aadcfa-0b44-474d-819b-a7de4d871f78","remaining_size":"2.10700000","product_id":"BTC-USD","sequence":10477649855,"time":"2019-08-08T10:10:35.205000Z"}
  {"type":"received","order_id":"433e521d-f048-448c-ba41-513011ab2140","order_type":"limit","size":"4.56500000","price":"11836.24000000","side":"sell","client_oid":"3acc7354-0852-476c-9f2e-1bcaf232f42e","product_id":"BTC-USD","sequence":10477649856,"time":"2019-08-08T10:10:35.215000Z"}
  {"type":"open","side":"sell","price":"11836.24000000","order_id":"433e521d-f048-448c-ba41-513011ab2140","remaining_size":"4.56500000","product_id":"BTC-USD","sequence":10477649857,"time":"2019-08-08T10:10:35.215000Z"}
  {"type":"done","side":"buy","order_id":"4311b3d6-1bfa-4c15-bf47-331bb1f51fba","reason":"canceled","product_id":"ETH-USD","price":"224.91000000","remaining_size":"38.26835685","sequence":7147163719,"time":"2019-08-08T10:10:35.218000Z"}
  {"type":"done","side":"sell","order_id":"3f00d4bb-a222-4767-9430-e58fe2aad5d7","reason":"canceled","product_id":"BTC-USD","price":"11836.24000000","remaining_size":"0.75000000","sequence":10477649858,"time":"2019-08-08T10:10:35.219000Z"}
  {"type":"done","side":"sell","order_id":"73498d70-f1ba-4bae-9c87-f6fbd03b6e93","reason":"canceled","product_id":"BTC-USD","price":"11836.25000000","remaining_size":"0.75000000","sequence":10477649859,"time":"2019-08-08T10:10:35.220000Z"}
  {"type":"done","side":"sell","order_id":"a2ef02a0-8ca4-4b04-9de1-9098075c7063","reason":"canceled","product_id":"BTC-USD","price":"11836.25000000","remaining_size":"0.50607637","sequence":10477649860,"time":"2019-08-08T10:10:35.223000Z"}
  {"type":"received","order_id":"19f609ea-035f-4959-864c-18dbcb1e4dfc","order_type":"limit","size":"0.75000000","price":"11836.23000000","side":"sell","client_oid":"178e5156-384c-4463-8b7b-5ee479e22122","product_id":"BTC-USD","sequence":10477649861,"time":"2019-08-08T10:10:35.225000Z"}
  {"type":"open","side":"sell","price":"11836.23000000","order_id":"19f609ea-035f-4959-864c-18dbcb1e4dfc","remaining_size":"0.75000000","product_id":"BTC-USD","sequence":10477649862,"time":"2019-08-08T10:10:35.225000Z"}
  {"type":"received","order_id":"bba5d075-1d9b-4311-a39c-af2d0d717e98","order_type":"limit","size":"0.75000000","price":"11836.23000000","side":"sell","client_oid":"aae5dda5-12da-4413-a594-5553c09e9025","product_id":"BTC-USD","sequence":10477649863,"time":"2019-08-08T10:10:35.231000Z"}
  {"type":"open","side":"sell","price":"11836.23000000","order_id":"bba5d075-1d9b-4311-a39c-af2d0d717e98","remaining_size":"0.75000000","product_id":"BTC-USD","sequence":10477649864,"time":"2019-08-08T10:10:35.231000Z"}
  {"type":"done","side":"sell","order_id":"433e521d-f048-448c-ba41-513011ab2140","reason":"canceled","product_id":"BTC-USD","price":"11836.24000000","remaining_size":"4.56500000","sequence":10477649865,"time":"2019-08-08T10:10:35.232000Z"}
  {"type":"done","side":"sell","order_id":"5cb20bf3-b47d-4b6f-b049-f1108c4bbb93","reason":"canceled","product_id":"BTC-USD","price":"11879.37000000","remaining_size":"0.00125508","sequence":10477649866,"time":"2019-08-08T10:10:35.235000Z"}
  {"type":"done","side":"buy","order_id":"6dd4b7fa-76d8-466b-bb49-52adb75c2d96","reason":"canceled","product_id":"BTC-USD","price":"11790.61000000","remaining_size":"0.00125507","sequence":10477649867,"time":"2019-08-08T10:10:35.235000Z"}
  {"type":"done","side":"buy","order_id":"b2b4903f-4e8f-4e8c-98f7-02c89844f69f","reason":"canceled","product_id":"BTC-USD","price":"11828.69000000","remaining_size":"0.13384019","sequence":10477649868,"time":"2019-08-08T10:10:35.236000Z"}
  {"type":"received","order_id":"01534401-05da-4711-9f21-212aca81d30d","order_type":"limit","size":"0.47118689","price":"11836.23000000","side":"sell","client_oid":"46b77b0f-c503-4575-9935-5334142f59d9","product_id":"BTC-USD","sequence":10477649869,"time":"2019-08-08T10:10:35.237000Z"}
  {"type":"open","side":"sell","price":"11836.23000000","order_id":"01534401-05da-4711-9f21-212aca81d30d","remaining_size":"0.47118689","product_id":"BTC-USD","sequence":10477649870,"time":"2019-08-08T10:10:35.237000Z"}
  {"type":"done","side":"buy","order_id":"ec530b1b-d3a0-4745-84b7-e874a75a1600","reason":"canceled","product_id":"BTC-USD","price":"11828.68000000","remaining_size":"0.13384019","sequence":10477649871,"time":"2019-08-08T10:10:35.238000Z"}
  {"type":"received","order_id":"b06551a6-d46c-4d33-835d-678ed93f2656","order_type":"limit","size":"0.01200000","price":"224.30000000","side":"buy","client_oid":"","product_id":"ETH-USD","sequence":7147163720,"time":"2019-08-08T10:10:35.241000Z"}
  {"type":"open","side":"buy","price":"224.30000000","order_id":"b06551a6-d46c-4d33-835d-678ed93f2656","remaining_size":"0.01200000","product_id":"ETH-USD","sequence":7147163721,"time":"2019-08-08T10:10:35.241000Z"}
  {"type":"received","order_id":"9d922622-3c5a-4f0a-bf91-a28a6980da67","order_type":"limit","size":"0.00125508","price":"11790.60000000","side":"buy","client_oid":"dfb2f4bc-3c71-4faf-8000-00de4927a332","product_id":"BTC-USD","sequence":10477649872,"time":"2019-08-08T10:10:35.242000Z"}
  {"type":"open","side":"buy","price":"11790.60000000","order_id":"9d922622-3c5a-4f0a-bf91-a28a6980da67","remaining_size":"0.00125508","product_id":"BTC-USD","sequence":10477649873,"time":"2019-08-08T10:10:35.242000Z"}
  {"type":"received","order_id":"b85d3ac4-fb50-45a8-8134-1fc6e8e5d6b3","order_type":"limit","size":"0.13384019","price":"11832.33000000","side":"buy","client_oid":"00000004-0000-0000-0000-000000872666","product_id":"BTC-USD","sequence":10477649874,"time":"2019-08-08T10:10:35.243000Z"}
  {"type":"open","side":"buy","price":"11832.33000000","order_id":"b85d3ac4-fb50-45a8-8134-1fc6e8e5d6b3","remaining_size":"0.13384019","product_id":"BTC-USD","sequence":10477649875,"time":"2019-08-08T10:10:35.243000Z"}
  {"type":"received","order_id":"0b29f9b8-4b77-402f-868f-174a717663fe","order_type":"limit","size":"4.56500000","price":"11836.23000000","side":"sell","client_oid":"86ac7ed7-380f-461d-aa5d-340834b6f550","product_id":"BTC-USD","sequence":10477649876,"time":"2019-08-08T10:10:35.245000Z"}
  {"type":"open","side":"sell","price":"11836.23000000","order_id":"0b29f9b8-4b77-402f-868f-174a717663fe","remaining_size":"4.56500000","product_id":"BTC-USD","sequence":10477649877,"time":"2019-08-08T10:10:35.245000Z"}
  {"type":"received","order_id":"5637b971-7f7d-4d18-a977-32a56f304f3f","order_type":"limit","size":"0.13384019","price":"11832.33000000","side":"buy","client_oid":"00000003-0000-0000-0000-000000872831","product_id":"BTC-USD","sequence":10477649878,"time":"2019-08-08T10:10:35.245000Z"}
  {"type":"open","side":"buy","price":"11832.33000000","order_id":"5637b971-7f7d-4d18-a977-32a56f304f3f","remaining_size":"0.13384019","product_id":"BTC-USD","sequence":10477649879,"time":"2019-08-08T10:10:35.245000Z"}
  {"type":"done","side":"sell","order_id":"19f609ea-035f-4959-864c-18dbcb1e4dfc","reason":"canceled","product_id":"BTC-USD","price":"11836.23000000","remaining_size":"0.75000000","sequence":10477649880,"time":"2019-08-08T10:10:35.250000Z"}
  {"type":"done","side":"buy","order_id":"b85d3ac4-fb50-45a8-8134-1fc6e8e5d6b3","reason":"canceled","product_id":"BTC-USD","price":"11832.33000000","remaining_size":"0.13384019","sequence":10477649881,"time":"2019-08-08T10:10:35.251000Z"}
  {"type":"done","side":"buy","order_id":"5637b971-7f7d-4d18-a977-32a56f304f3f","reason":"canceled","product_id":"BTC-USD","price":"11832.33000000","remaining_size":"0.13384019","sequence":10477649882,"time":"2019-08-08T10:10:35.251000Z"}
  {"type":"received","order_id":"b3148332-057d-48c9-bf38-e5d3431ddc24","order_type":"limit","size":"0.13384019","price":"11828.67000000","side":"buy","client_oid":"00000000-0000-0000-0000-000003009031","product_id":"BTC-USD","sequence":10477649883,"time":"2019-08-08T10:10:35.256000Z"}
  {"type":"open","side":"buy","price":"11828.67000000","order_id":"b3148332-057d-48c9-bf38-e5d3431ddc24","remaining_size":"0.13384019","product_id":"BTC-USD","sequence":10477649884,"time":"2019-08-08T10:10:35.256000Z"}
  {"type":"received","order_id":"2d229747-0bd0-440a-baed-06b78042759f","order_type":"limit","size":"0.75000000","price":"11836.22000000","side":"sell","client_oid":"13e29a0d-e192-4430-bdf2-512269fed8d8","product_id":"BTC-USD","sequence":10477649885,"time":"2019-08-08T10:10:35.257000Z"}
  {"type":"open","side":"sell","price":"11836.22000000","order_id":"2d229747-0bd0-440a-baed-06b78042759f","remaining_size":"0.75000000","product_id":"BTC-USD","sequence":10477649886,"time":"2019-08-08T10:10:35.257000Z"}
  {"type":"received","order_id":"fe7ae286-4770-4fd6-9e0f-72ac209f525b","order_type":"limit","size":"0.00125508","price":"11879.36000000","side":"sell","client_oid":"c4a1c672-896a-4e43-8000-001630ee47a6","product_id":"BTC-USD","sequence":10477649887,"time":"2019-08-08T10:10:35.260000Z"}
  {"type":"open","side":"sell","price":"11879.36000000","order_id":"fe7ae286-4770-4fd6-9e0f-72ac209f525b","remaining_size":"0.00125508","product_id":"BTC-USD","sequence":10477649888,"time":"2019-08-08T10:10:35.260000Z"}
  {"type":"received","order_id":"76d3bfe9-06b0-4912-8cba-7aac0230ec81","order_type":"limit","size":"0.13384019","price":"11828.67000000","side":"buy","client_oid":"00000001-0000-0000-0000-000002991860","product_id":"BTC-USD","sequence":10477649889,"time":"2019-08-08T10:10:35.261000Z"}
  {"type":"open","side":"buy","price":"11828.67000000","order_id":"76d3bfe9-06b0-4912-8cba-7aac0230ec81","remaining_size":"0.13384019","product_id":"BTC-USD","sequence":10477649890,"time":"2019-08-08T10:10:35.261000Z"}
  {"type":"done","side":"sell","order_id":"0b29f9b8-4b77-402f-868f-174a717663fe","reason":"canceled","product_id":"BTC-USD","price":"11836.23000000","remaining_size":"4.56500000","sequence":10477649891,"time":"2019-08-08T10:10:35.266000Z"}
  {"type":"received","order_id":"d03998db-1f86-423d-8027-c5d3d964b68c","order_type":"limit","size":"4.56500000","price":"11836.22000000","side":"sell","client_oid":"09e0132d-b4ea-4254-a79f-4a25df5375e0","product_id":"BTC-USD","sequence":10477649892,"time":"2019-08-08T10:10:35.288000Z"}
  {"type":"open","side":"sell","price":"11836.22000000","order_id":"d03998db-1f86-423d-8027-c5d3d964b68c","remaining_size":"4.56500000","product_id":"BTC-USD","sequence":10477649893,"time":"2019-08-08T10:10:35.288000Z"}
  {"type":"done","side":"sell","order_id":"2d229747-0bd0-440a-baed-06b78042759f","reason":"canceled","product_id":"BTC-USD","price":"11836.22000000","remaining_size":"0.75000000","sequence":10477649894,"time":"2019-08-08T10:10:35.292000Z"}
  {"type":"done","side":"sell","order_id":"bba5d075-1d9b-4311-a39c-af2d0d717e98","reason":"canceled","product_id":"BTC-USD","price":"11836.23000000","remaining_size":"0.75000000","sequence":10477649895,"time":"2019-08-08T10:10:35.293000Z"}
  {"type":"received","order_id":"37764e11-05e5-401c-bb15-fff517d9c945","order_type":"limit","size":"0.01000000","price":"11784.17000000","side":"buy","client_oid":"a42d9442-8ed1-474a-8783-8212c3e50a01","product_id":"BTC-USD","sequence":10477649896,"time":"2019-08-08T10:10:35.296000Z"}
  {"type":"open","side":"buy","price":"11784.17000000","order_id":"37764e11-05e5-401c-bb15-fff517d9c945","remaining_size":"0.01000000","product_id":"BTC-USD","sequence":10477649897,"time":"2019-08-08T10:10:35.296000Z"}
  {"type":"received","order_id":"3f49837c-25db-492f-88f7-7aaf69efa389","order_type":"limit","size":"0.75000000","price":"11836.21000000","side":"sell","client_oid":"c59e68f3-7926-4947-96ba-5265606c583b","product_id":"BTC-USD","sequence":10477649898,"time":"2019-08-08T10:10:35.301000Z"}
  {"type":"open","side":"sell","price":"11836.21000000","order_id":"3f49837c-25db-492f-88f7-7aaf69efa389","remaining_size":"0.75000000","product_id":"BTC-USD","sequence":10477649899,"time":"2019-08-08T10:10:35.301000Z"}
  {"type":"done","side":"sell","order_id":"d03998db-1f86-423d-8027-c5d3d964b68c","reason":"canceled","product_id":"BTC-USD","price":"11836.22000000","remaining_size":"4.56500000","sequence":10477649900,"time":"2019-08-08T10:10:35.305000Z"}
  {"type":"received","order_id":"74694562-f420-477d-9386-0218441cb3c6","order_type":"limit","size":"4.56500000","price":"11836.21000000","side":"sell","client_oid":"23023af5-7f21-40d5-9cfb-e083247c967c","product_id":"BTC-USD","sequence":10477649901,"time":"2019-08-08T10:10:35.314000Z"}
  {"type":"open","side":"sell","price":"11836.21000000","order_id":"74694562-f420-477d-9386-0218441cb3c6","remaining_size":"4.56500000","product_id":"BTC-USD","sequence":10477649902,"time":"2019-08-08T10:10:35.314000Z"}
  {"type":"received","order_id":"21c210e3-66bd-4570-9bec-3373af6682dd","order_type":"limit","size":"38.26835685","price":"224.91000000","side":"buy","client_oid":"d9f88082-5d38-bd7c-b2fb-74f0f3304100","product_id":"ETH-USD","sequence":7147163722,"time":"2019-08-08T10:10:35.323000Z"}
  {"type":"open","side":"buy","price":"224.91000000","order_id":"21c210e3-66bd-4570-9bec-3373af6682dd","remaining_size":"38.26835685","product_id":"ETH-USD","sequence":7147163723,"time":"2019-08-08T10:10:35.323000Z"}
  {"type":"received","order_id":"1f721400-3e70-4e26-a0a9-1bc919c4a825","order_type":"limit","size":"0.01100000","price":"224.25000000","side":"buy","client_oid":"","product_id":"ETH-USD","sequence":7147163724,"time":"2019-08-08T10:10:35.326000Z"}
  {"type":"open","side":"buy","price":"224.25000000","order_id":"1f721400-3e70-4e26-a0a9-1bc919c4a825","remaining_size":"0.01100000","product_id":"ETH-USD","sequence":7147163725,"time":"2019-08-08T10:10:35.326000Z"}
  {"type":"done","side":"buy","order_id":"21c210e3-66bd-4570-9bec-3373af6682dd","reason":"canceled","product_id":"ETH-USD","price":"224.91000000","remaining_size":"38.26835685","sequence":7147163726,"time":"2019-08-08T10:10:35.333000Z"}
  {"type":"done","side":"sell","order_id":"01534401-05da-4711-9f21-212aca81d30d","reason":"canceled","product_id":"BTC-USD","price":"11836.23000000","remaining_size":"0.47118689","sequence":10477649903,"time":"2019-08-08T10:10:35.345000Z"}
  {"type":"done","side":"buy","order_id":"9d922622-3c5a-4f0a-bf91-a28a6980da67","reason":"canceled","product_id":"BTC-USD","price":"11790.60000000","remaining_size":"0.00125508","sequence":10477649904,"time":"2019-08-08T10:10:35.345000Z"}
  {"type":"received","order_id":"e39ec723-8fbe-4a37-9d37-8faf9aa19714","order_type":"limit","size":"0.06154672","price":"11836.23000000","side":"sell","client_oid":"4c512176-a5d0-4fbd-aaee-b57a20507b26","product_id":"BTC-USD","sequence":10477649905,"time":"2019-08-08T10:10:35.351000Z"}
  {"type":"open","side":"sell","price":"11836.23000000","order_id":"e39ec723-8fbe-4a37-9d37-8faf9aa19714","remaining_size":"0.06154672","product_id":"BTC-USD","sequence":10477649906,"time":"2019-08-08T10:10:35.351000Z"}
  {"type":"received","order_id":"ddfcff83-7524-4c0a-a660-d0f08fb7d278","order_type":"limit","size":"0.00125508","price":"11790.59000000","side":"buy","client_oid":"6eff1222-0126-4e9c-8000-0068fa42a0c3","product_id":"BTC-USD","sequence":10477649907,"time":"2019-08-08T10:10:35.351000Z"}
  {"type":"open","side":"buy","price":"11790.59000000","order_id":"ddfcff83-7524-4c0a-a660-d0f08fb7d278","remaining_size":"0.00125508","product_id":"BTC-USD","sequence":10477649908,"time":"2019-08-08T10:10:35.351000Z"}
  {"type":"done","side":"sell","order_id":"fe7ae286-4770-4fd6-9e0f-72ac209f525b","reason":"canceled","product_id":"BTC-USD","price":"11879.36000000","remaining_size":"0.00125508","sequence":10477649909,"time":"2019-08-08T10:10:35.355000Z"}
  {"type":"received","order_id":"adc4f83d-eb8e-4fbe-a481-73b59fcbc95d","order_type":"limit","size":"0.51383453","price":"11836.21000000","side":"sell","client_oid":"70d6c33e-f7f0-4131-9fe9-19db03b6e9c2","product_id":"BTC-USD","sequence":10477649910,"time":"2019-08-08T10:10:35.355000Z"}
  {"type":"open","side":"sell","price":"11836.21000000","order_id":"adc4f83d-eb8e-4fbe-a481-73b59fcbc95d","remaining_size":"0.51383453","product_id":"BTC-USD","sequence":10477649911,"time":"2019-08-08T10:10:35.355000Z"}
  {"type":"done","side":"sell","order_id":"e39ec723-8fbe-4a37-9d37-8faf9aa19714","reason":"canceled","product_id":"BTC-USD","price":"11836.23000000","remaining_size":"0.06154672","sequence":10477649912,"time":"2019-08-08T10:10:35.358000Z"}
  {"type":"received","order_id":"64dec983-c51e-49f1-9d7f-97ff153a953b","order_type":"limit","size":"0.35130557","price":"11836.20000000","side":"sell","client_oid":"52a5a2f8-2fbb-4b0f-9f70-dccdaa5f4946","product_id":"BTC-USD","sequence":10477649913,"time":"2019-08-08T10:10:35.360000Z"}
  {"type":"open","side":"sell","price":"11836.20000000","order_id":"64dec983-c51e-49f1-9d7f-97ff153a953b","remaining_size":"0.35130557","product_id":"BTC-USD","sequence":10477649914,"time":"2019-08-08T10:10:35.360000Z"}
  {"type":"done","side":"sell","order_id":"adc4f83d-eb8e-4fbe-a481-73b59fcbc95d","reason":"canceled","product_id":"BTC-USD","price":"11836.21000000","remaining_size":"0.51383453","sequence":10477649915,"time":"2019-08-08T10:10:35.361000Z"}
  {"type":"done","side":"sell","order_id":"74694562-f420-477d-9386-0218441cb3c6","reason":"canceled","product_id":"BTC-USD","price":"11836.21000000","remaining_size":"4.56500000","sequence":10477649916,"time":"2019-08-08T10:10:35.366000Z"}
  {"type":"received","order_id":"45ba9425-6e7f-48bb-b20b-2ac4e75e33a4","order_type":"limit","size":"4.56500000","price":"11836.20000000","side":"sell","client_oid":"2b24daa0-c944-4a10-8b47-fd7ab8cee403","product_id":"BTC-USD","sequence":10477649917,"time":"2019-08-08T10:10:35.375000Z"}
  {"type":"open","side":"sell","price":"11836.20000000","order_id":"45ba9425-6e7f-48bb-b20b-2ac4e75e33a4","remaining_size":"4.56500000","product_id":"BTC-USD","sequence":10477649918,"time":"2019-08-08T10:10:35.375000Z"}
  {"type":"received","order_id":"d5b23496-3054-41eb-a220-a35ab1ef75d8","order_type":"limit","size":"0.75000000","price":"11836.19000000","side":"sell","client_oid":"8b0bca4e-d8e1-40c8-b11f-51dd560c1d13","product_id":"BTC-USD","sequence":10477649919,"time":"2019-08-08T10:10:35.397000Z"}
  {"type":"open","side":"sell","price":"11836.19000000","order_id":"d5b23496-3054-41eb-a220-a35ab1ef75d8","remaining_size":"0.75000000","product_id":"BTC-USD","sequence":10477649920,"time":"2019-08-08T10:10:35.397000Z"}
  {"type":"received","order_id":"a1fa9a1e-098e-44c7-b024-92ce6820eb4c","order_type":"limit","size":"0.75000000","price":"11836.20000000","side":"sell","client_oid":"cf73eb2d-b113-4637-8af8-faba8370850d","product_id":"BTC-USD","sequence":10477649921,"time":"2019-08-08T10:10:35.399000Z"}
  {"type":"open","side":"sell","price":"11836.20000000","order_id":"a1fa9a1e-098e-44c7-b024-92ce6820eb4c","remaining_size":"0.75000000","product_id":"BTC-USD","sequence":10477649922,"time":"2019-08-08T10:10:35.399000Z"}
  {"type":"done","side":"sell","order_id":"3f49837c-25db-492f-88f7-7aaf69efa389","reason":"canceled","product_id":"BTC-USD","price":"11836.21000000","remaining_size":"0.75000000","sequence":10477649923,"time":"2019-08-08T10:10:35.401000Z"}
  {"type":"done","side":"sell","order_id":"45ba9425-6e7f-48bb-b20b-2ac4e75e33a4","reason":"canceled","product_id":"BTC-USD","price":"11836.20000000","remaining_size":"4.56500000","sequence":10477649924,"time":"2019-08-08T10:10:35.401000Z"}
  {"type":"done","side":"sell","order_id":"a1fa9a1e-098e-44c7-b024-92ce6820eb4c","reason":"canceled","product_id":"BTC-USD","price":"11836.20000000","remaining_size":"0.75000000","sequence":10477649925,"time":"2019-08-08T10:10:35.403000Z"}
  {"type":"received","order_id":"150e77c2-a715-4383-8d18-91ded1e9a9e1","order_type":"limit","size":"0.75000000","price":"11836.19000000","side":"sell","client_oid":"9b158f55-a326-43bf-96a9-dd954c344474","product_id":"BTC-USD","sequence":10477649926,"time":"2019-08-08T10:10:35.408000Z"}
  {"type":"open","side":"sell","price":"11836.19000000","order_id":"150e77c2-a715-4383-8d18-91ded1e9a9e1","remaining_size":"0.75000000","product_id":"BTC-USD","sequence":10477649927,"time":"2019-08-08T10:10:35.408000Z"}
  {"type":"received","order_id":"1289050f-7610-4ce7-abee-52244db57471","order_type":"limit","size":"4.56500000","price":"11836.19000000","side":"sell","client_oid":"686bd90e-b42f-4c07-958c-bc02e6834447","product_id":"BTC-USD","sequence":10477649928,"time":"2019-08-08T10:10:35.413000Z"}
  {"type":"open","side":"sell","price":"11836.19000000","order_id":"1289050f-7610-4ce7-abee-52244db57471","remaining_size":"4.56500000","product_id":"BTC-USD","sequence":10477649929,"time":"2019-08-08T10:10:35.413000Z"}
  {"type":"done","side":"sell","order_id":"d5b23496-3054-41eb-a220-a35ab1ef75d8","reason":"canceled","product_id":"BTC-USD","price":"11836.19000000","remaining_size":"0.75000000","sequence":10477649930,"time":"2019-08-08T10:10:35.416000Z"}
  {"type":"done","side":"buy","order_id":"ddfcff83-7524-4c0a-a660-d0f08fb7d278","reason":"canceled","product_id":"BTC-USD","price":"11790.59000000","remaining_size":"0.00125508","sequence":10477649931,"time":"2019-08-08T10:10:35.421000Z"}
  {"type":"received","order_id":"dbcdb0d4-813e-4c1d-ba5f-d79aa989b80e","order_type":"limit","size":"0.00125508","price":"11790.58000000","side":"buy","client_oid":"bd2a3dad-b60a-46f3-8000-0009778094c6","product_id":"BTC-USD","sequence":10477649932,"time":"2019-08-08T10:10:35.428000Z"}
  {"type":"open","side":"buy","price":"11790.58000000","order_id":"dbcdb0d4-813e-4c1d-ba5f-d79aa989b80e","remaining_size":"0.00125508","product_id":"BTC-USD","sequence":10477649933,"time":"2019-08-08T10:10:35.428000Z"}
  {"type":"received","order_id":"4da50378-7b09-4082-a49b-c4ede6be15a1","order_type":"limit","size":"0.00125508","price":"11879.34000000","side":"sell","client_oid":"53c92f9c-9180-430b-8000-0093551f454f","product_id":"BTC-USD","sequence":10477649934,"time":"2019-08-08T10:10:35.428000Z"}
  {"type":"open","side":"sell","price":"11879.34000000","order_id":"4da50378-7b09-4082-a49b-c4ede6be15a1","remaining_size":"0.00125508","product_id":"BTC-USD","sequence":10477649935,"time":"2019-08-08T10:10:35.428000Z"}
  {"type":"done","side":"buy","order_id":"b0d0b367-54c5-4492-ae86-f9a87df03313","reason":"canceled","product_id":"BTC-USD","price":"11814.75000000","remaining_size":"0.90400000","sequence":10477649936,"time":"2019-08-08T10:10:35.489000Z"}
  {"type":"done","side":"sell","order_id":"a6273d34-f160-4cfd-be3f-729b2fb1712b","reason":"canceled","product_id":"BTC-USD","price":"11836.26000000","remaining_size":"0.02000000","sequence":10477649937,"time":"2019-08-08T10:10:35.499000Z"}
  {"type":"done","side":"sell","order_id":"a10c935a-e702-4b7b-99eb-8b56e4c0c2a6","reason":"canceled","product_id":"BTC-USD","price":"11841.52000000","remaining_size":"3.00000000","sequence":10477649938,"time":"2019-08-08T10:10:35.522000Z"}
  {"type":"received","order_id":"32c75fbe-75ac-4997-94e6-253e44219363","order_type":"limit","size":"0.02000000","price":"11836.18000000","side":"sell","client_oid":"00000003-5969-2183-2942-171441159763","product_id":"BTC-USD","sequence":10477649939,"time":"2019-08-08T10:10:35.556000Z"}
  {"type":"open","side":"sell","price":"11836.18000000","order_id":"32c75fbe-75ac-4997-94e6-253e44219363","remaining_size":"0.02000000","product_id":"BTC-USD","sequence":10477649940,"time":"2019-08-08T10:10:35.556000Z"}
  {"type":"done","side":"sell","order_id":"1289050f-7610-4ce7-abee-52244db57471","reason":"canceled","product_id":"BTC-USD","price":"11836.19000000","remaining_size":"4.56500000","sequence":10477649941,"time":"2019-08-08T10:10:35.561000Z"}
  {"type":"done","side":"sell","order_id":"64dec983-c51e-49f1-9d7f-97ff153a953b","reason":"canceled","product_id":"BTC-USD","price":"11836.20000000","remaining_size":"0.35130557","sequence":10477649942,"time":"2019-08-08T10:10:35.561000Z"}
  {"type":"received","order_id":"6a4afd76-f913-43ce-ad64-dc799022e6bb","order_type":"limit","size":"0.01000000","price":"224.20000000","side":"buy","client_oid":"","product_id":"ETH-USD","sequence":7147163727,"time":"2019-08-08T10:10:35.564000Z"}
  {"type":"open","side":"buy","price":"224.20000000","order_id":"6a4afd76-f913-43ce-ad64-dc799022e6bb","remaining_size":"0.01000000","product_id":"ETH-USD","sequence":7147163728,"time":"2019-08-08T10:10:35.564000Z"}
  {"type":"received","order_id":"f8eaf703-b46f-4fc1-901b-183bc8d45148","order_type":"limit","size":"0.23983905","price":"11836.18000000","side":"sell","client_oid":"2063b586-19ba-4b6c-8b4c-3be59edb0ddd","product_id":"BTC-USD","sequence":10477649943,"time":"2019-08-08T10:10:35.566000Z"}
  {"type":"open","side":"sell","price":"11836.18000000","order_id":"f8eaf703-b46f-4fc1-901b-183bc8d45148","remaining_size":"0.23983905","product_id":"BTC-USD","sequence":10477649944,"time":"2019-08-08T10:10:35.566000Z"}
  {"type":"done","side":"buy","order_id":"b3148332-057d-48c9-bf38-e5d3431ddc24","reason":"canceled","product_id":"BTC-USD","price":"11828.67000000","remaining_size":"0.13384019","sequence":10477649945,"time":"2019-08-08T10:10:35.567000Z"}
  {"type":"done","side":"buy","order_id":"76d3bfe9-06b0-4912-8cba-7aac0230ec81","reason":"canceled","product_id":"BTC-USD","price":"11828.67000000","remaining_size":"0.13384019","sequence":10477649946,"time":"2019-08-08T10:10:35.567000Z"}
  {"type":"received","order_id":"c8180721-8be4-4006-9946-dd27fe2fadfb","order_type":"limit","size":"3.00000000","price":"11844.16000000","side":"sell","client_oid":"20202020-2020-2020-852f-f2ea6369bc07","product_id":"BTC-USD","sequence":10477649947,"time":"2019-08-08T10:10:35.570000Z"}
  {"type":"open","side":"sell","price":"11844.16000000","order_id":"c8180721-8be4-4006-9946-dd27fe2fadfb","remaining_size":"3.00000000","product_id":"BTC-USD","sequence":10477649948,"time":"2019-08-08T10:10:35.570000Z"}
  {"type":"received","order_id":"36ee8dbd-af6f-49e3-a08a-6a73fe38eca0","order_type":"limit","size":"0.75000000","price":"11836.18000000","side":"sell","client_oid":"36c7167c-0b11-41b8-8338-f29596a0a517","product_id":"BTC-USD","sequence":10477649949,"time":"2019-08-08T10:10:35.573000Z"}
  {"type":"open","side":"sell","price":"11836.18000000","order_id":"36ee8dbd-af6f-49e3-a08a-6a73fe38eca0","remaining_size":"0.75000000","product_id":"BTC-USD","sequence":10477649950,"time":"2019-08-08T10:10:35.573000Z"}
  {"type":"received","order_id":"49581d2a-b56a-4703-844e-3a713e116731","order_type":"limit","size":"0.13384075","price":"11832.33000000","side":"buy","client_oid":"00000003-0000-0000-0000-000000872833","product_id":"BTC-USD","sequence":10477649951,"time":"2019-08-08T10:10:35.573000Z"}
  {"type":"open","side":"buy","price":"11832.33000000","order_id":"49581d2a-b56a-4703-844e-3a713e116731","remaining_size":"0.13384075","product_id":"BTC-USD","sequence":10477649952,"time":"2019-08-08T10:10:35.573000Z"}
  {"type":"received","order_id":"bedca12f-e45d-4082-9a48-cb7b258e531d","order_type":"limit","size":"0.13384064","price":"11832.33000000","side":"buy","client_oid":"00000002-0000-0000-0000-000002991487","product_id":"BTC-USD","sequence":10477649953,"time":"2019-08-08T10:10:35.575000Z"}
  {"type":"open","side":"buy","price":"11832.33000000","order_id":"bedca12f-e45d-4082-9a48-cb7b258e531d","remaining_size":"0.13384064","product_id":"BTC-USD","sequence":10477649954,"time":"2019-08-08T10:10:35.575000Z"}
  {"type":"received","order_id":"d5f45718-6520-47c4-869b-3af70fbff74d","order_type":"limit","size":"4.56500000","price":"11836.18000000","side":"sell","client_oid":"b8d0d741-4f76-44f8-8ef1-78c1de06eebf","product_id":"BTC-USD","sequence":10477649955,"time":"2019-08-08T10:10:35.575000Z"}
  {"type":"open","side":"sell","price":"11836.18000000","order_id":"d5f45718-6520-47c4-869b-3af70fbff74d","remaining_size":"4.56500000","product_id":"BTC-USD","sequence":10477649956,"time":"2019-08-08T10:10:35.575000Z"}
  {"type":"done","side":"buy","order_id":"bedca12f-e45d-4082-9a48-cb7b258e531d","reason":"canceled","product_id":"BTC-USD","price":"11832.33000000","remaining_size":"0.13384064","sequence":10477649957,"time":"2019-08-08T10:10:35.580000Z"}
  {"type":"done","side":"buy","order_id":"49581d2a-b56a-4703-844e-3a713e116731","reason":"canceled","product_id":"BTC-USD","price":"11832.33000000","remaining_size":"0.13384075","sequence":10477649958,"time":"2019-08-08T10:10:35.581000Z"}
  {"type":"received","order_id":"4d0b7677-c2a5-4cfc-934e-ac20aab23288","order_type":"limit","size":"0.13384075","price":"11828.67000000","side":"buy","client_oid":"00000000-0000-0000-0000-000003009033","product_id":"BTC-USD","sequence":10477649959,"time":"2019-08-08T10:10:35.587000Z"}
  {"type":"open","side":"buy","price":"11828.67000000","order_id":"4d0b7677-c2a5-4cfc-934e-ac20aab23288","remaining_size":"0.13384075","product_id":"BTC-USD","sequence":10477649960,"time":"2019-08-08T10:10:35.587000Z"}
  {"type":"received","order_id":"aa0a903f-6780-4c49-865e-bd42c114aa0b","order_type":"limit","size":"0.90400000","price":"11811.17000000","side":"buy","client_oid":"4c46376f-9c0d-47a3-9a5d-b225c28d3487","product_id":"BTC-USD","sequence":10477649961,"time":"2019-08-08T10:10:35.588000Z"}
  {"type":"open","side":"buy","price":"11811.17000000","order_id":"aa0a903f-6780-4c49-865e-bd42c114aa0b","remaining_size":"0.90400000","product_id":"BTC-USD","sequence":10477649962,"time":"2019-08-08T10:10:35.588000Z"}
  {"type":"received","order_id":"00b7784a-8c2f-490c-880f-8e171e41026c","order_type":"limit","size":"38.26835685","price":"224.91000000","side":"buy","client_oid":"d9f88082-5d38-bd7c-b2fb-8621f3304100","product_id":"ETH-USD","sequence":7147163729,"time":"2019-08-08T10:10:35.633000Z"}
  {"type":"open","side":"buy","price":"224.91000000","order_id":"00b7784a-8c2f-490c-880f-8e171e41026c","remaining_size":"38.26835685","product_id":"ETH-USD","sequence":7147163730,"time":"2019-08-08T10:10:35.633000Z"}
  {"type":"done","side":"buy","order_id":"00b7784a-8c2f-490c-880f-8e171e41026c","reason":"canceled","product_id":"ETH-USD","price":"224.91000000","remaining_size":"38.26835685","sequence":7147163731,"time":"2019-08-08T10:10:35.647000Z"}
  {"type":"received","order_id":"23e19a22-30ba-40c7-9f2c-82b71119911b","order_type":"limit","size":"0.13384064","price":"11828.67000000","side":"buy","client_oid":"00000004-0000-0000-0000-000000872668","product_id":"BTC-USD","sequence":10477649963,"time":"2019-08-08T10:10:35.671000Z"}
  {"type":"open","side":"buy","price":"11828.67000000","order_id":"23e19a22-30ba-40c7-9f2c-82b71119911b","remaining_size":"0.13384064","product_id":"BTC-USD","sequence":10477649964,"time":"2019-08-08T10:10:35.671000Z"}
  {"type":"received","order_id":"916fa8f8-14f7-4211-bd9f-ba9a574295ad","order_type":"limit","size":"38.26835685","price":"224.91000000","side":"buy","client_oid":"d9f88082-5d38-bd7c-b2fb-5141f3304100","product_id":"ETH-USD","sequence":7147163732,"time":"2019-08-08T10:10:35.773000Z"}
  {"type":"open","side":"buy","price":"224.91000000","order_id":"916fa8f8-14f7-4211-bd9f-ba9a574295ad","remaining_size":"38.26835685","product_id":"ETH-USD","sequence":7147163733,"time":"2019-08-08T10:10:35.773000Z"}
  {"type":"done","side":"sell","order_id":"150e77c2-a715-4383-8d18-91ded1e9a9e1","reason":"canceled","product_id":"BTC-USD","price":"11836.19000000","remaining_size":"0.75000000","sequence":10477649965,"time":"2019-08-08T10:10:35.776000Z"}
  {"type":"done","side":"buy","order_id":"916fa8f8-14f7-4211-bd9f-ba9a574295ad","reason":"canceled","product_id":"ETH-USD","price":"224.91000000","remaining_size":"38.26835685","sequence":7147163734,"time":"2019-08-08T10:10:35.782000Z"}
  {"type":"done","side":"sell","order_id":"32c75fbe-75ac-4997-94e6-253e44219363","reason":"canceled","product_id":"BTC-USD","price":"11836.18000000","remaining_size":"0.02000000","sequence":10477649966,"time":"2019-08-08T10:10:35.822000Z"}
  {"type":"done","side":"sell","order_id":"07aadcfa-0b44-474d-819b-a7de4d871f78","reason":"canceled","product_id":"BTC-USD","price":"11843.44000000","remaining_size":"2.10700000","sequence":10477649967,"time":"2019-08-08T10:10:35.823000Z"}
  {"type":"received","order_id":"77faeda3-216a-434c-bc0a-acbf1f98472f","order_type":"limit","size":"0.02000000","price":"11836.38000000","side":"sell","client_oid":"00000003-2765-9799-4437-216491567788","product_id":"BTC-USD","sequence":10477649968,"time":"2019-08-08T10:10:35.827000Z"}
  {"type":"open","side":"sell","price":"11836.38000000","order_id":"77faeda3-216a-434c-bc0a-acbf1f98472f","remaining_size":"0.02000000","product_id":"BTC-USD","sequence":10477649969,"time":"2019-08-08T10:10:35.827000Z"}
  {"type":"received","order_id":"fa2e2257-255e-4678-b769-7911e1114efe","order_type":"limit","size":"2.10600000","price":"11844.34000000","side":"sell","client_oid":"c04b80c0-2c20-490c-8a1e-ec3add0d6371","product_id":"BTC-USD","sequence":10477649970,"time":"2019-08-08T10:10:35.829000Z"}
  {"type":"open","side":"sell","price":"11844.34000000","order_id":"fa2e2257-255e-4678-b769-7911e1114efe","remaining_size":"2.10600000","product_id":"BTC-USD","sequence":10477649971,"time":"2019-08-08T10:10:35.829000Z"}
  {"type":"received","order_id":"066e17f4-bf03-453c-8f2f-29ebb6624da3","order_type":"limit","size":"0.75000000","price":"11836.17000000","side":"sell","client_oid":"f82d75b6-1064-4726-a69e-89ff60465efe","product_id":"BTC-USD","sequence":10477649972,"time":"2019-08-08T10:10:35.831000Z"}
  {"type":"open","side":"sell","price":"11836.17000000","order_id":"066e17f4-bf03-453c-8f2f-29ebb6624da3","remaining_size":"0.75000000","product_id":"BTC-USD","sequence":10477649973,"time":"2019-08-08T10:10:35.831000Z"}
  {"type":"done","side":"sell","order_id":"4da50378-7b09-4082-a49b-c4ede6be15a1","reason":"canceled","product_id":"BTC-USD","price":"11879.34000000","remaining_size":"0.00125508","sequence":10477649974,"time":"2019-08-08T10:10:35.840000Z"}
  {"type":"done","side":"buy","order_id":"dbcdb0d4-813e-4c1d-ba5f-d79aa989b80e","reason":"canceled","product_id":"BTC-USD","price":"11790.58000000","remaining_size":"0.00125508","sequence":10477649975,"time":"2019-08-08T10:10:35.840000Z"}
  {"type":"done","side":"sell","order_id":"d5f45718-6520-47c4-869b-3af70fbff74d","reason":"canceled","product_id":"BTC-USD","price":"11836.18000000","remaining_size":"4.56500000","sequence":10477649976,"time":"2019-08-08T10:10:35.841000Z"}
  {"type":"received","order_id":"04341ac2-2790-46fa-a074-aa671db7d2ac","order_type":"limit","size":"0.00125508","price":"11790.57000000","side":"buy","client_oid":"4d4cb922-89d9-48d5-8000-00b56fd81b02","product_id":"BTC-USD","sequence":10477649977,"time":"2019-08-08T10:10:35.847000Z"}
  {"type":"open","side":"buy","price":"11790.57000000","order_id":"04341ac2-2790-46fa-a074-aa671db7d2ac","remaining_size":"0.00125508","product_id":"BTC-USD","sequence":10477649978,"time":"2019-08-08T10:10:35.847000Z"}
  {"type":"done","side":"sell","order_id":"36ee8dbd-af6f-49e3-a08a-6a73fe38eca0","reason":"canceled","product_id":"BTC-USD","price":"11836.18000000","remaining_size":"0.75000000","sequence":10477649979,"time":"2019-08-08T10:10:35.847000Z"}
  {"type":"received","order_id":"a6a9833f-45b9-49f7-8350-537d109ecb63","order_type":"limit","size":"4.56500000","price":"11836.17000000","side":"sell","client_oid":"19d4f2b9-33f2-4fff-a8df-5ac9d393c693","product_id":"BTC-USD","sequence":10477649980,"time":"2019-08-08T10:10:35.858000Z"}
  {"type":"open","side":"sell","price":"11836.17000000","order_id":"a6a9833f-45b9-49f7-8350-537d109ecb63","remaining_size":"4.56500000","product_id":"BTC-USD","sequence":10477649981,"time":"2019-08-08T10:10:35.858000Z"}
  {"type":"received","order_id":"baa0cfd3-6f28-45c9-bd1e-8bd0189ef36b","order_type":"limit","size":"38.26835685","price":"224.91000000","side":"buy","client_oid":"d9f88082-5d38-bd7c-b2fb-4351f3304100","product_id":"ETH-USD","sequence":7147163735,"time":"2019-08-08T10:10:35.864000Z"}
  {"type":"open","side":"buy","price":"224.91000000","order_id":"baa0cfd3-6f28-45c9-bd1e-8bd0189ef36b","remaining_size":"38.26835685","product_id":"ETH-USD","sequence":7147163736,"time":"2019-08-08T10:10:35.864000Z"}
  {"type":"received","order_id":"372f1f61-8a03-4ef2-81ae-2a2d2989d44c","order_type":"limit","size":"0.00125508","price":"11879.33000000","side":"sell","client_oid":"2e40a075-a6ab-4be0-8000-0605401f52b0","product_id":"BTC-USD","sequence":10477649982,"time":"2019-08-08T10:10:35.863000Z"}
  {"type":"open","side":"sell","price":"11879.33000000","order_id":"372f1f61-8a03-4ef2-81ae-2a2d2989d44c","remaining_size":"0.00125508","product_id":"BTC-USD","sequence":10477649983,"time":"2019-08-08T10:10:35.863000Z"}
  {"type":"received","order_id":"d511e35d-64b6-49a7-aa3c-00accb641dce","order_type":"limit","size":"0.75000000","price":"11836.16000000","side":"sell","client_oid":"9ab2b9ef-2e2b-4b95-b768-0b8aada80589","product_id":"BTC-USD","sequence":10477649984,"time":"2019-08-08T10:10:35.869000Z"}
  {"type":"open","side":"sell","price":"11836.16000000","order_id":"d511e35d-64b6-49a7-aa3c-00accb641dce","remaining_size":"0.75000000","product_id":"BTC-USD","sequence":10477649985,"time":"2019-08-08T10:10:35.869000Z"}
  {"type":"done","side":"sell","order_id":"a6a9833f-45b9-49f7-8350-537d109ecb63","reason":"canceled","product_id":"BTC-USD","price":"11836.17000000","remaining_size":"4.56500000","sequence":10477649986,"time":"2019-08-08T10:10:35.873000Z"}
  {"type":"done","side":"sell","order_id":"f8eaf703-b46f-4fc1-901b-183bc8d45148","reason":"canceled","product_id":"BTC-USD","price":"11836.18000000","remaining_size":"0.23983905","sequence":10477649987,"time":"2019-08-08T10:10:35.873000Z"}
  {"type":"received","order_id":"2213a2e2-b77f-4bba-b23b-e7717c5cf556","order_type":"limit","size":"0.30513849","price":"11836.16000000","side":"sell","client_oid":"b9f5172a-e227-4218-92fe-a5ed2aae259e","product_id":"BTC-USD","sequence":10477649988,"time":"2019-08-08T10:10:35.879000Z"}
  {"type":"open","side":"sell","price":"11836.16000000","order_id":"2213a2e2-b77f-4bba-b23b-e7717c5cf556","remaining_size":"0.30513849","product_id":"BTC-USD","sequence":10477649989,"time":"2019-08-08T10:10:35.879000Z"}
  {"type":"received","order_id":"3b7b061f-ceb1-44c6-9c73-15a4ecf5e9fc","order_type":"limit","size":"4.56500000","price":"11836.16000000","side":"sell","client_oid":"b2f944cf-986a-4bbf-af7a-26bfd01232ea","product_id":"BTC-USD","sequence":10477649990,"time":"2019-08-08T10:10:35.924000Z"}
  {"type":"open","side":"sell","price":"11836.16000000","order_id":"3b7b061f-ceb1-44c6-9c73-15a4ecf5e9fc","remaining_size":"4.56500000","product_id":"BTC-USD","sequence":10477649991,"time":"2019-08-08T10:10:35.924000Z"}
  {"type":"done","side":"buy","order_id":"baa0cfd3-6f28-45c9-bd1e-8bd0189ef36b","reason":"canceled","product_id":"ETH-USD","price":"224.91000000","remaining_size":"38.26835685","sequence":7147163737,"time":"2019-08-08T10:10:35.930000Z"}
  {"type":"done","side":"sell","order_id":"d511e35d-64b6-49a7-aa3c-00accb641dce","reason":"canceled","product_id":"BTC-USD","price":"11836.16000000","remaining_size":"0.75000000","sequence":10477649992,"time":"2019-08-08T10:10:35.929000Z"}
  {"type":"heartbeat","last_trade_id":0,"product_id":"BTC-USD","sequence":10477649992,"time":"2019-08-08T10:10:35.933366Z"}
  {"type":"received","order_id":"b470c1cc-c74e-4ae4-ab6f-65daff9fd609","order_type":"limit","size":"0.75000000","price":"11836.15000000","side":"sell","client_oid":"d7a4a950-d4cb-4c63-8d20-41fe98b25a92","product_id":"BTC-USD","sequence":10477649993,"time":"2019-08-08T10:10:35.935000Z"}
  {"type":"open","side":"sell","price":"11836.15000000","order_id":"b470c1cc-c74e-4ae4-ab6f-65daff9fd609","remaining_size":"0.75000000","product_id":"BTC-USD","sequence":10477649994,"time":"2019-08-08T10:10:35.935000Z"}
  {"type":"done","side":"sell","order_id":"066e17f4-bf03-453c-8f2f-29ebb6624da3","reason":"canceled","product_id":"BTC-USD","price":"11836.17000000","remaining_size":"0.75000000","sequence":10477649995,"time":"2019-08-08T10:10:35.940000Z"}
  {"type":"done","side":"sell","order_id":"3b7b061f-ceb1-44c6-9c73-15a4ecf5e9fc","reason":"canceled","product_id":"BTC-USD","price":"11836.16000000","remaining_size":"4.56500000","sequence":10477649996,"time":"2019-08-08T10:10:35.945000Z"}
  {"type":"done","side":"sell","order_id":"372f1f61-8a03-4ef2-81ae-2a2d2989d44c","reason":"canceled","product_id":"BTC-USD","price":"11879.33000000","remaining_size":"0.00125508","sequence":10477649997,"time":"2019-08-08T10:10:35.947000Z"}
  {"type":"done","side":"buy","order_id":"04341ac2-2790-46fa-a074-aa671db7d2ac","reason":"canceled","product_id":"BTC-USD","price":"11790.57000000","remaining_size":"0.00125508","sequence":10477649998,"time":"2019-08-08T10:10:35.947000Z"}
  {"type":"heartbeat","last_trade_id":0,"product_id":"ETH-USD","sequence":7147163737,"time":"2019-08-08T10:10:35.953488Z"}
  {"type":"received","order_id":"782660e0-a952-4868-8289-0e22a6f0cfc9","order_type":"limit","size":"0.11525200","price":"11836.16000000","side":"sell","client_oid":"2bcbe6ef-8b97-4aa7-a903-2a778eb1e0cc","product_id":"BTC-USD","sequence":10477649999,"time":"2019-08-08T10:10:35.952000Z"}
  {"type":"open","side":"sell","price":"11836.16000000","order_id":"782660e0-a952-4868-8289-0e22a6f0cfc9","remaining_size":"0.11525200","product_id":"BTC-USD","sequence":10477650000,"time":"2019-08-08T10:10:35.952000Z"}
  {"type":"received","order_id":"6769395e-fb67-464d-a6f8-3ac8ec10270f","order_type":"limit","size":"0.00125508","price":"11790.56000000","side":"buy","client_oid":"47781504-484e-4587-8000-00549e3d1453","product_id":"BTC-USD","sequence":10477650001,"time":"2019-08-08T10:10:35.954000Z"}
  {"type":"open","side":"buy","price":"11790.56000000","order_id":"6769395e-fb67-464d-a6f8-3ac8ec10270f","remaining_size":"0.00125508","product_id":"BTC-USD","sequence":10477650002,"time":"2019-08-08T10:10:35.954000Z"}
  {"type":"received","order_id":"37ed10cd-13a8-4c3f-ac72-e748a2928988","order_type":"limit","size":"0.75000000","price":"11836.15000000","side":"sell","client_oid":"d57b209d-2474-48eb-8d58-fb154ef361aa","product_id":"BTC-USD","sequence":10477650003,"time":"2019-08-08T10:10:35.954000Z"}
  {"type":"open","side":"sell","price":"11836.15000000","order_id":"37ed10cd-13a8-4c3f-ac72-e748a2928988","remaining_size":"0.75000000","product_id":"BTC-USD","sequence":10477650004,"time":"2019-08-08T10:10:35.954000Z"}
  {"type":"received","order_id":"42b7ca01-fe4c-4731-9d9a-9bab42f032d9","order_type":"limit","size":"4.56500000","price":"11836.15000000","side":"sell","client_oid":"d209448c-a8f2-426b-9ee0-5ffbda60d2ba","product_id":"BTC-USD","sequence":10477650005,"time":"2019-08-08T10:10:35.955000Z"}
  {"type":"open","side":"sell","price":"11836.15000000","order_id":"42b7ca01-fe4c-4731-9d9a-9bab42f032d9","remaining_size":"4.56500000","product_id":"BTC-USD","sequence":10477650006,"time":"2019-08-08T10:10:35.955000Z"}
  {"type":"done","side":"sell","order_id":"b470c1cc-c74e-4ae4-ab6f-65daff9fd609","reason":"canceled","product_id":"BTC-USD","price":"11836.15000000","remaining_size":"0.75000000","sequence":10477650007,"time":"2019-08-08T10:10:35.959000Z"}
  {"type":"received","order_id":"3585fda7-2b75-482e-a793-f9cb120294b0","order_type":"limit","size":"0.75000000","price":"11836.14000000","side":"sell","client_oid":"8e70be09-6293-413c-99c2-7309b7870140","product_id":"BTC-USD","sequence":10477650008,"time":"2019-08-08T10:10:35.965000Z"}
  {"type":"open","side":"sell","price":"11836.14000000","order_id":"3585fda7-2b75-482e-a793-f9cb120294b0","remaining_size":"0.75000000","product_id":"BTC-USD","sequence":10477650009,"time":"2019-08-08T10:10:35.965000Z"}
  {"type":"received","order_id":"ddae99df-3d59-47b7-8cdc-8f04b84fec2d","order_type":"limit","size":"0.00125508","price":"11879.32000000","side":"sell","client_oid":"94bb67d3-0b8f-4bca-8000-006236d2a914","product_id":"BTC-USD","sequence":10477650010,"time":"2019-08-08T10:10:35.967000Z"}
  {"type":"open","side":"sell","price":"11879.32000000","order_id":"ddae99df-3d59-47b7-8cdc-8f04b84fec2d","remaining_size":"0.00125508","product_id":"BTC-USD","sequence":10477650011,"time":"2019-08-08T10:10:35.967000Z"}
  {"type":"done","side":"sell","order_id":"42b7ca01-fe4c-4731-9d9a-9bab42f032d9","reason":"canceled","product_id":"BTC-USD","price":"11836.15000000","remaining_size":"4.56500000","sequence":10477650012,"time":"2019-08-08T10:10:35.969000Z"}
  {"type":"done","side":"sell","order_id":"2213a2e2-b77f-4bba-b23b-e7717c5cf556","reason":"canceled","product_id":"BTC-USD","price":"11836.16000000","remaining_size":"0.30513849","sequence":10477650013,"time":"2019-08-08T10:10:35.970000Z"}
  {"type":"done","side":"sell","order_id":"782660e0-a952-4868-8289-0e22a6f0cfc9","reason":"canceled","product_id":"BTC-USD","price":"11836.16000000","remaining_size":"0.11525200","sequence":10477650014,"time":"2019-08-08T10:10:35.970000Z"}
  {"type":"received","order_id":"fe9110bd-b150-4126-9022-5b9868e501b1","order_type":"limit","size":"0.41525373","price":"11836.14000000","side":"sell","client_oid":"05c5d2f4-60cc-4a55-966c-d22c843bdc48","product_id":"BTC-USD","sequence":10477650015,"time":"2019-08-08T10:10:35.977000Z"}
  {"type":"open","side":"sell","price":"11836.14000000","order_id":"fe9110bd-b150-4126-9022-5b9868e501b1","remaining_size":"0.41525373","product_id":"BTC-USD","sequence":10477650016,"time":"2019-08-08T10:10:35.977000Z"}
  {"type":"received","order_id":"6970538e-a8ba-45b9-baca-1dd449821950","order_type":"limit","size":"4.56500000","price":"11836.14000000","side":"sell","client_oid":"bb92c41b-0e8a-4b6d-b3eb-3bde3a40a76d","product_id":"BTC-USD","sequence":10477650017,"time":"2019-08-08T10:10:35.979000Z"}
  {"type":"open","side":"sell","price":"11836.14000000","order_id":"6970538e-a8ba-45b9-baca-1dd449821950","remaining_size":"4.56500000","product_id":"BTC-USD","sequence":10477650018,"time":"2019-08-08T10:10:35.979000Z"}
  {"type":"done","side":"sell","order_id":"3585fda7-2b75-482e-a793-f9cb120294b0","reason":"canceled","product_id":"BTC-USD","price":"11836.14000000","remaining_size":"0.75000000","sequence":10477650019,"time":"2019-08-08T10:10:35.983000Z"}
  {"type":"received","order_id":"7d2fe2dd-71f0-4dfa-a079-5455cd770895","order_type":"limit","size":"0.75000000","price":"11836.13000000","side":"sell","client_oid":"cf2f092c-a608-40f0-a124-58210e7029fd","product_id":"BTC-USD","sequence":10477650020,"time":"2019-08-08T10:10:35.991000Z"}
  {"type":"open","side":"sell","price":"11836.13000000","order_id":"7d2fe2dd-71f0-4dfa-a079-5455cd770895","remaining_size":"0.75000000","product_id":"BTC-USD","sequence":10477650021,"time":"2019-08-08T10:10:35.991000Z"}
  {"type":"done","side":"sell","order_id":"37ed10cd-13a8-4c3f-ac72-e748a2928988","reason":"canceled","product_id":"BTC-USD","price":"11836.15000000","remaining_size":"0.75000000","sequence":10477650022,"time":"2019-08-08T10:10:35.995000Z"}
  {"type":"done","side":"sell","order_id":"6970538e-a8ba-45b9-baca-1dd449821950","reason":"canceled","product_id":"BTC-USD","price":"11836.14000000","remaining_size":"4.56500000","sequence":10477650023,"time":"2019-08-08T10:10:35.996000Z"}
  {"type":"done","side":"sell","order_id":"5aef1cc0-73fa-4df3-b37a-9f17103ee36a","reason":"canceled","product_id":"BTC-USD","price":"11836.42000000","remaining_size":"0.01000000","sequence":10477650024,"time":"2019-08-08T10:10:36.100000Z"}
  {"type":"done","side":"sell","order_id":"ddae99df-3d59-47b7-8cdc-8f04b84fec2d","reason":"canceled","product_id":"BTC-USD","price":"11879.32000000","remaining_size":"0.00125508","sequence":10477650025,"time":"2019-08-08T10:10:36.400000Z"}
  {"type":"done","side":"buy","order_id":"23e19a22-30ba-40c7-9f2c-82b71119911b","reason":"canceled","product_id":"BTC-USD","price":"11828.67000000","remaining_size":"0.13384064","sequence":10477650026,"time":"2019-08-08T10:10:36.700000Z"}
  {"type":"received","order_id":"e4a8442c-2d8d-4b96-8c66-bc1689213e2a","order_type":"limit","size":"4.56500000","price":"11836.13000000","side":"sell","client_oid":"84ba9473-8276-4d1f-9b9c-721abfed413f","product_id":"BTC-USD","sequence":10477650027,"time":"2019-08-08T10:10:36.900000Z"}
  {"type":"open","side":"sell","price":"11836.13000000","order_id":"e4a8442c-2d8d-4b96-8c66-bc1689213e2a","remaining_size":"4.56500000","product_id":"BTC-USD","sequence":10477650028,"time":"2019-08-08T10:10:36.900000Z"}
  {"type":"received","order_id":"e2a83ead-35da-4c82-a07d-7aa1a2c2e10f","order_type":"limit","size":"0.01000000","price":"11836.13000000","side":"buy","client_oid":"ea9825e3-b377-4055-999a-1adc5161801e","product_id":"BTC-USD","sequence":10477650029,"time":"2019-08-08T10:10:36.100000Z"}
  {"type":"match","trade_id":71752029,"maker_order_id":"7d2fe2dd-71f0-4dfa-a079-5455cd770895","taker_order_id":"e2a83ead-35da-4c82-a07d-7aa1a2c2e10f","side":"sell","size":"0.01000000","price":"11836.13000000","product_id":"BTC-USD","sequence":10477650030,"time":"2019-08-08T10:10:36.100000Z"}
  {"type":"done","side":"buy","order_id":"e2a83ead-35da-4c82-a07d-7aa1a2c2e10f","reason":"filled","product_id":"BTC-USD","price":"11836.13000000","remaining_size":"0.00000000","sequence":10477650031,"time":"2019-08-08T10:10:36.100000Z"}
  {"type":"received","order_id":"047f00a7-4874-4eef-bbec-7b309f066a9e","order_type":"limit","size":"0.13384075","price":"11832.33000000","side":"buy","client_oid":"00000002-0000-0000-0000-000002991489","product_id":"BTC-USD","sequence":10477650032,"time":"2019-08-08T10:10:36.120000Z"}
  {"type":"open","side":"buy","price":"11832.33000000","order_id":"047f00a7-4874-4eef-bbec-7b309f066a9e","remaining_size":"0.13384075","product_id":"BTC-USD","sequence":10477650033,"time":"2019-08-08T10:10:36.120000Z"}
  {"type":"received","order_id":"305467c0-f572-42b6-a668-754234b24fd5","order_type":"limit","size":"0.13384064","price":"11832.33000000","side":"buy","client_oid":"00000001-0000-0000-0000-000002991862","product_id":"BTC-USD","sequence":10477650034,"time":"2019-08-08T10:10:36.140000Z"}
  {"type":"open","side":"buy","price":"11832.33000000","order_id":"305467c0-f572-42b6-a668-754234b24fd5","remaining_size":"0.13384064","product_id":"BTC-USD","sequence":10477650035,"time":"2019-08-08T10:10:36.140000Z"}
  {"type":"done","side":"sell","order_id":"7d2fe2dd-71f0-4dfa-a079-5455cd770895","reason":"canceled","product_id":"BTC-USD","price":"11836.13000000","remaining_size":"0.74000000","sequence":10477650036,"time":"2019-08-08T10:10:36.150000Z"}
  {"type":"done","side":"buy","order_id":"047f00a7-4874-4eef-bbec-7b309f066a9e","reason":"canceled","product_id":"BTC-USD","price":"11832.33000000","remaining_size":"0.13384075","sequence":10477650037,"time":"2019-08-08T10:10:36.160000Z"}
  {"type":"done","side":"sell","order_id":"fe9110bd-b150-4126-9022-5b9868e501b1","reason":"canceled","product_id":"BTC-USD","price":"11836.14000000","remaining_size":"0.41525373","sequence":10477650038,"time":"2019-08-08T10:10:36.160000Z"}
  {"type":"done","side":"buy","order_id":"305467c0-f572-42b6-a668-754234b24fd5","reason":"canceled","product_id":"BTC-USD","price":"11832.33000000","remaining_size":"0.13384064","sequence":10477650039,"time":"2019-08-08T10:10:36.200000Z"}
  {"type":"received","order_id":"75ba5e49-5649-4e37-8d98-7c057d1d96ce","order_type":"limit","size":"0.08706649","price":"11836.12000000","side":"sell","client_oid":"d86a22b8-a1dd-45fb-88a4-c0f1ac62585a","product_id":"BTC-USD","sequence":10477650040,"time":"2019-08-08T10:10:36.220000Z"}
  {"type":"open","side":"sell","price":"11836.12000000","order_id":"75ba5e49-5649-4e37-8d98-7c057d1d96ce","remaining_size":"0.08706649","product_id":"BTC-USD","sequence":10477650041,"time":"2019-08-08T10:10:36.220000Z"}
  {"type":"received","order_id":"12b3c17f-3cbc-423f-b3c4-e150e91a0d3b","order_type":"limit","size":"0.13384064","price":"11828.68000000","side":"buy","client_oid":"00000003-0000-0000-0000-000000872835","product_id":"BTC-USD","sequence":10477650042,"time":"2019-08-08T10:10:36.270000Z"}
  {"type":"open","side":"buy","price":"11828.68000000","order_id":"12b3c17f-3cbc-423f-b3c4-e150e91a0d3b","remaining_size":"0.13384064","product_id":"BTC-USD","sequence":10477650043,"time":"2019-08-08T10:10:36.270000Z"}
  {"type":"done","side":"sell","order_id":"37dd4e1c-b6ff-4bc3-a29b-213882ab5603","reason":"canceled","product_id":"ETH-USD","price":"225.20000000","remaining_size":"0.22830327","sequence":7147163738,"time":"2019-08-08T10:10:36.300000Z"}
  {"type":"received","order_id":"27af367a-733a-45b8-ae4e-3129331edcf4","order_type":"limit","size":"0.13384075","price":"11828.68000000","side":"buy","client_oid":"00000004-0000-0000-0000-000000872670","product_id":"BTC-USD","sequence":10477650044,"time":"2019-08-08T10:10:36.290000Z"}
  {"type":"open","side":"buy","price":"11828.68000000","order_id":"27af367a-733a-45b8-ae4e-3129331edcf4","remaining_size":"0.13384075","product_id":"BTC-USD","sequence":10477650045,"time":"2019-08-08T10:10:36.290000Z"}
  {"type":"done","side":"sell","order_id":"3ec1d67c-f51f-4d1d-8b27-86149bb0d2eb","reason":"canceled","product_id":"ETH-USD","price":"225.20000000","remaining_size":"0.11829833","sequence":7147163739,"time":"2019-08-08T10:10:36.330000Z"}
  {"type":"done","side":"sell","order_id":"69142edb-6560-43d6-9b2a-637b2070957b","reason":"canceled","product_id":"ETH-USD","price":"225.20000000","remaining_size":"0.33432480","sequence":7147163740,"time":"2019-08-08T10:10:36.330000Z"}
  {"type":"done","side":"sell","order_id":"5a0069b5-e7a4-4ae9-bcd9-9c7d32013840","reason":"canceled","product_id":"ETH-USD","price":"225.20000000","remaining_size":"1.31907360","sequence":7147163741,"time":"2019-08-08T10:10:36.340000Z"}
  {"type":"done","side":"sell","order_id":"e4a8442c-2d8d-4b96-8c66-bc1689213e2a","reason":"canceled","product_id":"BTC-USD","price":"11836.13000000","remaining_size":"4.56500000","sequence":10477650046,"time":"2019-08-08T10:10:36.350000Z"}
  {"type":"done","side":"buy","order_id":"e612003f-cfd8-487f-af9e-7dfb8d3091fa","reason":"canceled","product_id":"BTC-USD","price":"11818.59000000","remaining_size":"3.00000000","sequence":10477650047,"time":"2019-08-08T10:10:36.360000Z"}
  {"type":"done","side":"sell","order_id":"3bcb9013-e346-4ac1-bb60-033f7eabb173","reason":"canceled","product_id":"BTC-USD","price":"11853.59000000","remaining_size":"6.00000000","sequence":10477650048,"time":"2019-08-08T10:10:36.400000Z"}
  {"type":"done","side":"buy","order_id":"e332112b-fbdd-4607-8356-257627a92948","reason":"canceled","product_id":"BTC-USD","price":"11804.80000000","remaining_size":"6.00000000","sequence":10477650049,"time":"2019-08-08T10:10:36.400000Z"}
  {"type":"done","side":"sell","order_id":"c8180721-8be4-4006-9946-dd27fe2fadfb","reason":"canceled","product_id":"BTC-USD","price":"11844.16000000","remaining_size":"3.00000000","sequence":10477650050,"time":"2019-08-08T10:10:36.400000Z"}
  {"type":"done","side":"buy","order_id":"12b3c17f-3cbc-423f-b3c4-e150e91a0d3b","reason":"canceled","product_id":"BTC-USD","price":"11828.68000000","remaining_size":"0.13384064","sequence":10477650051,"time":"2019-08-08T10:10:36.400000Z"}
  {"type":"done","side":"sell","order_id":"77faeda3-216a-434c-bc0a-acbf1f98472f","reason":"canceled","product_id":"BTC-USD","price":"11836.38000000","remaining_size":"0.02000000","sequence":10477650052,"time":"2019-08-08T10:10:36.680000Z"}
  {"type":"received","order_id":"400557a9-ad22-4950-a194-507c20110c6e","order_type":"limit","size":"0.02000000","price":"11836.11000000","side":"sell","client_oid":"00000003-6627-2293-6264-667838557971","product_id":"BTC-USD","sequence":10477650053,"time":"2019-08-08T10:10:36.710000Z"}
  {"type":"open","side":"sell","price":"11836.11000000","order_id":"400557a9-ad22-4950-a194-507c20110c6e","remaining_size":"0.02000000","product_id":"BTC-USD","sequence":10477650054,"time":"2019-08-08T10:10:36.710000Z"}
  {"type":"received","order_id":"22d18cbf-7dc8-4540-b13a-53120158353b","order_type":"limit","size":"3.00000000","price":"11822.17000000","side":"buy","client_oid":"20202020-2020-2020-99e6-1fe3320fc11f","product_id":"BTC-USD","sequence":10477650055,"time":"2019-08-08T10:10:36.730000Z"}
  {"type":"open","side":"buy","price":"11822.17000000","order_id":"22d18cbf-7dc8-4540-b13a-53120158353b","remaining_size":"3.00000000","product_id":"BTC-USD","sequence":10477650056,"time":"2019-08-08T10:10:36.730000Z"}
  {"type":"done","side":"sell","order_id":"ef262858-b2e1-490c-8938-be05d11108bf","reason":"canceled","product_id":"ETH-USD","price":"225.20000000","remaining_size":"2.00000000","sequence":7147163742,"time":"2019-08-08T10:10:36.780000Z"}
  {"type":"done","side":"buy","order_id":"6769395e-fb67-464d-a6f8-3ac8ec10270f","reason":"canceled","product_id":"BTC-USD","price":"11790.56000000","remaining_size":"0.00125508","sequence":10477650057,"time":"2019-08-08T10:10:36.780000Z"}
  {"type":"received","order_id":"c2a26fe2-f5e8-4833-bb54-402948aa4387","order_type":"limit","size":"6.00000000","price":"11858.90000000","side":"sell","client_oid":"20202020-2020-2020-b697-7bdc8a6fecec","product_id":"BTC-USD","sequence":10477650058,"time":"2019-08-08T10:10:36.800000Z"}
  {"type":"open","side":"sell","price":"11858.90000000","order_id":"c2a26fe2-f5e8-4833-bb54-402948aa4387","remaining_size":"6.00000000","product_id":"BTC-USD","sequence":10477650059,"time":"2019-08-08T10:10:36.800000Z"}
  {"type":"received","order_id":"e7aa3814-51f4-45a4-85b7-381d1c14a498","order_type":"limit","size":"0.00125508","price":"11879.31000000","side":"sell","client_oid":"911733a8-8338-4d61-8000-0a7bbfec5940","product_id":"BTC-USD","sequence":10477650060,"time":"2019-08-08T10:10:36.810000Z"}
  {"type":"open","side":"sell","price":"11879.31000000","order_id":"e7aa3814-51f4-45a4-85b7-381d1c14a498","remaining_size":"0.00125508","product_id":"BTC-USD","sequence":10477650061,"time":"2019-08-08T10:10:36.810000Z"}
  {"type":"done","side":"buy","order_id":"4d0b7677-c2a5-4cfc-934e-ac20aab23288","reason":"canceled","product_id":"BTC-USD","price":"11828.67000000","remaining_size":"0.13384075","sequence":10477650062,"time":"2019-08-08T10:10:36.900000Z"}
  {"type":"received","order_id":"c6715adb-9dfe-45c5-95cb-7d02c20bbf8c","order_type":"limit","size":"0.00125508","price":"11790.54000000","side":"buy","client_oid":"26c2434c-fab7-4026-8000-009ca78d4678","product_id":"BTC-USD","sequence":10477650063,"time":"2019-08-08T10:10:36.910000Z"}
  {"type":"open","side":"buy","price":"11790.54000000","order_id":"c6715adb-9dfe-45c5-95cb-7d02c20bbf8c","remaining_size":"0.00125508","product_id":"BTC-USD","sequence":10477650064,"time":"2019-08-08T10:10:36.910000Z"}
  {"type":"received","order_id":"d835ade5-7dbd-4edc-acc6-5be515203f8a","order_type":"limit","size":"38.26835685","price":"224.97000000","side":"buy","client_oid":"d9f88082-5d38-bd7c-b2fb-3d81f3304100","product_id":"ETH-USD","sequence":7147163743,"time":"2019-08-08T10:10:36.930000Z"}
  {"type":"open","side":"buy","price":"224.97000000","order_id":"d835ade5-7dbd-4edc-acc6-5be515203f8a","remaining_size":"38.26835685","product_id":"ETH-USD","sequence":7147163744,"time":"2019-08-08T10:10:36.930000Z"}
  {"type":"received","order_id":"53cf86b3-9a81-4f1d-b21d-e5d18fe0f0f5","order_type":"limit","size":"6.00000000","price":"11810.09000000","side":"buy","client_oid":"20202020-2020-2020-b810-3dc975c05fae","product_id":"BTC-USD","sequence":10477650065,"time":"2019-08-08T10:10:36.930000Z"}
  {"type":"open","side":"buy","price":"11810.09000000","order_id":"53cf86b3-9a81-4f1d-b21d-e5d18fe0f0f5","remaining_size":"6.00000000","product_id":"BTC-USD","sequence":10477650066,"time":"2019-08-08T10:10:36.940000Z"}
  {"type":"received","order_id":"91058066-6419-44c1-8072-7191c2d853a1","order_type":"limit","size":"3.00000000","price":"11846.83000000","side":"sell","client_oid":"20202020-2020-2020-b0a5-e43abfd16309","product_id":"BTC-USD","sequence":10477650067,"time":"2019-08-08T10:10:36.940000Z"}
  {"type":"open","side":"sell","price":"11846.83000000","order_id":"91058066-6419-44c1-8072-7191c2d853a1","remaining_size":"3.00000000","product_id":"BTC-USD","sequence":10477650068,"time":"2019-08-08T10:10:36.940000Z"}
  {"type":"done","side":"buy","order_id":"27af367a-733a-45b8-ae4e-3129331edcf4","reason":"canceled","product_id":"BTC-USD","price":"11828.68000000","remaining_size":"0.13384075","sequence":10477650069,"time":"2019-08-08T10:10:36.960000Z"}
  {"type":"received","order_id":"100e3513-2b57-4f9a-b48d-2c40508ab4d7","order_type":"limit","size":"0.13384075","price":"11832.33000000","side":"buy","client_oid":"00000001-0000-0000-0000-000002991864","product_id":"BTC-USD","sequence":10477650070,"time":"2019-08-08T10:10:36.104000Z"}
  {"type":"open","side":"buy","price":"11832.33000000","order_id":"100e3513-2b57-4f9a-b48d-2c40508ab4d7","remaining_size":"0.13384075","product_id":"BTC-USD","sequence":10477650071,"time":"2019-08-08T10:10:36.104000Z"}
  {"type":"received","order_id":"cef0b45b-1255-43db-ab42-fba835b2653e","order_type":"limit","size":"0.66633192","price":"11833.69000000","side":"buy","client_oid":"7802c8da-b8b2-4ac5-8402-4867d57ad46b","product_id":"BTC-USD","sequence":10477650072,"time":"2019-08-08T10:10:36.114000Z"}
  {"type":"open","side":"buy","price":"11833.69000000","order_id":"cef0b45b-1255-43db-ab42-fba835b2653e","remaining_size":"0.66633192","product_id":"BTC-USD","sequence":10477650073,"time":"2019-08-08T10:10:36.114000Z"}
  {"type":"received","order_id":"7dc6284f-45f4-4c6a-86cd-69acf287af93","order_type":"limit","size":"0.13384064","price":"11832.33000000","side":"buy","client_oid":"00000000-0000-0000-0000-000003009035","product_id":"BTC-USD","sequence":10477650074,"time":"2019-08-08T10:10:36.114000Z"}
  {"type":"open","side":"buy","price":"11832.33000000","order_id":"7dc6284f-45f4-4c6a-86cd-69acf287af93","remaining_size":"0.13384064","product_id":"BTC-USD","sequence":10477650075,"time":"2019-08-08T10:10:36.114000Z"}
  {"type":"received","order_id":"ec7abf2c-deda-4425-b481-3acf0cb52ba6","order_type":"limit","size":"0.03042707","price":"11833.69000000","side":"buy","client_oid":"82e7ac9b-8b0c-4f61-9409-04b26ac65c7a","product_id":"BTC-USD","sequence":10477650076,"time":"2019-08-08T10:10:36.114000Z"}
  {"type":"open","side":"buy","price":"11833.69000000","order_id":"ec7abf2c-deda-4425-b481-3acf0cb52ba6","remaining_size":"0.03042707","product_id":"BTC-USD","sequence":10477650077,"time":"2019-08-08T10:10:36.114000Z"}
  {"type":"received","order_id":"54624758-447b-44b2-825c-3b718846559e","order_type":"limit","size":"0.10000000","price":"11780.08000000","side":"buy","client_oid":"2761d518-d9b9-41e4-b4d7-3297a29e9a09","product_id":"BTC-USD","sequence":10477650078,"time":"2019-08-08T10:10:36.138000Z"}
  {"type":"open","side":"buy","price":"11780.08000000","order_id":"54624758-447b-44b2-825c-3b718846559e","remaining_size":"0.10000000","product_id":"BTC-USD","sequence":10477650079,"time":"2019-08-08T10:10:36.138000Z"}
  {"type":"done","side":"buy","order_id":"37764e11-05e5-401c-bb15-fff517d9c945","reason":"canceled","product_id":"BTC-USD","price":"11784.17000000","remaining_size":"0.01000000","sequence":10477650080,"time":"2019-08-08T10:10:36.162000Z"}
  {"type":"received","order_id":"aa61806b-56a7-4e4f-8621-7f695b8263be","order_type":"limit","size":"1.00000000","price":"11813.21000000","side":"buy","client_oid":"c23b8a16-0bfc-54a5-6e28-7ac135a329a9","product_id":"BTC-USD","sequence":10477650081,"time":"2019-08-08T10:10:36.236000Z"}
  {"type":"open","side":"buy","price":"11813.21000000","order_id":"aa61806b-56a7-4e4f-8621-7f695b8263be","remaining_size":"1.00000000","product_id":"BTC-USD","sequence":10477650082,"time":"2019-08-08T10:10:36.236000Z"}
  {"type":"done","side":"sell","order_id":"3875c315-c8e9-41d1-a361-2ffc56ec54e0","reason":"canceled","product_id":"BTC-USD","price":"12448.28000000","remaining_size":"0.00100796","sequence":10477650083,"time":"2019-08-08T10:10:36.252000Z"}
  {"type":"done","side":"buy","order_id":"f868c79c-fdb0-4705-8eff-df09d1c74d43","reason":"canceled","product_id":"BTC-USD","price":"11303.74000000","remaining_size":"0.00310928","sequence":10477650084,"time":"2019-08-08T10:10:36.252000Z"}
  {"type":"done","side":"sell","order_id":"a403170d-70fc-4108-9060-1e3d5304b7f2","reason":"canceled","product_id":"BTC-USD","price":"12069.78000000","remaining_size":"0.00100831","sequence":10477650085,"time":"2019-08-08T10:10:36.262000Z"}
  {"type":"received","order_id":"4c4d2009-eeea-4104-ac76-a75a271875ff","order_type":"limit","size":"13.28550000","price":"225.81000000","side":"sell","client_oid":"fb4a31f3-4989-4e3b-8b26-c70fc0ae41f6","product_id":"ETH-USD","sequence":7147163745,"time":"2019-08-08T10:10:36.310000Z"}
  {"type":"open","side":"sell","price":"225.81000000","order_id":"4c4d2009-eeea-4104-ac76-a75a271875ff","remaining_size":"13.28550000","product_id":"ETH-USD","sequence":7147163746,"time":"2019-08-08T10:10:36.310000Z"}
  {"type":"done","side":"buy","order_id":"aa61806b-56a7-4e4f-8621-7f695b8263be","reason":"canceled","product_id":"BTC-USD","price":"11813.21000000","remaining_size":"1.00000000","sequence":10477650086,"time":"2019-08-08T10:10:36.332000Z"}
  {"type":"received","order_id":"ade61408-0193-4f86-94ae-a92386ef75a4","order_type":"limit","size":"4.13000000","price":"11824.43000000","side":"buy","client_oid":"074b92ef-621f-fd8c-30f3-fc8649b22471","product_id":"BTC-USD","sequence":10477650087,"time":"2019-08-08T10:10:36.338000Z"}
  {"type":"open","side":"buy","price":"11824.43000000","order_id":"ade61408-0193-4f86-94ae-a92386ef75a4","remaining_size":"4.13000000","product_id":"BTC-USD","sequence":10477650088,"time":"2019-08-08T10:10:36.338000Z"}
  {"type":"done","side":"buy","order_id":"dd33727d-1266-42e5-a229-0c350df2732a","reason":"canceled","product_id":"BTC-USD","price":"11794.96000000","remaining_size":"0.46700000","sequence":10477650089,"time":"2019-08-08T10:10:36.494000Z"}
  {"type":"received","order_id":"fad6d1a7-09e1-4941-bb41-6795c47c8379","order_type":"limit","size":"0.83900000","price":"11860.06000000","side":"sell","client_oid":"76cee6df-6fad-4097-980c-05ba53b1c025","product_id":"BTC-USD","sequence":10477650090,"time":"2019-08-08T10:10:36.529000Z"}
  {"type":"open","side":"sell","price":"11860.06000000","order_id":"fad6d1a7-09e1-4941-bb41-6795c47c8379","remaining_size":"0.83900000","product_id":"BTC-USD","sequence":10477650091,"time":"2019-08-08T10:10:36.529000Z"}
  {"type":"done","side":"sell","order_id":"34c3c94a-2bf3-4226-99a2-00b53045ccf2","reason":"canceled","product_id":"ETH-USD","price":"225.21000000","remaining_size":"10.00000000","sequence":7147163747,"time":"2019-08-08T10:10:36.586000Z"}
  {"type":"received","order_id":"dc8a59ac-79bc-4862-bf14-55ac2a89f5ec","order_type":"limit","size":"10.00000000","price":"225.17000000","side":"buy","client_oid":"b7ad1284-6f7c-411d-bf14-deb3e0fd7dbd","product_id":"ETH-USD","sequence":7147163748,"time":"2019-08-08T10:10:36.605000Z"}
  {"type":"open","side":"buy","price":"225.17000000","order_id":"dc8a59ac-79bc-4862-bf14-55ac2a89f5ec","remaining_size":"10.00000000","product_id":"ETH-USD","sequence":7147163749,"time":"2019-08-08T10:10:36.605000Z"}
  {"type":"done","side":"buy","order_id":"7de54aea-9327-41a6-979b-8caed2e18881","reason":"canceled","product_id":"ETH-USD","price":"225.16000000","remaining_size":"2.16100556","sequence":7147163750,"time":"2019-08-08T10:10:36.612000Z"}
  {"type":"done","side":"buy","order_id":"9cebe60c-02b9-40ad-83f5-c9881066fec7","reason":"canceled","product_id":"ETH-USD","price":"225.16000000","remaining_size":"2.19217124","sequence":7147163751,"time":"2019-08-08T10:10:36.613000Z"}
  {"type":"received","order_id":"52db5e68-2e3b-4246-a284-592e6d3ae2b4","order_type":"limit","size":"2.01796475","price":"225.18000000","side":"buy","client_oid":"00000002-0000-0000-0000-000002991491","product_id":"ETH-USD","sequence":7147163752,"time":"2019-08-08T10:10:36.617000Z"}
  {"type":"open","side":"buy","price":"225.18000000","order_id":"52db5e68-2e3b-4246-a284-592e6d3ae2b4","remaining_size":"2.01796475","product_id":"ETH-USD","sequence":7147163753,"time":"2019-08-08T10:10:36.617000Z"}
  {"type":"done","side":"buy","order_id":"c81160e0-87ab-4879-bc1f-6c3c6201019b","reason":"canceled","product_id":"ETH-USD","price":"225.06000000","remaining_size":"2.00000000","sequence":7147163754,"time":"2019-08-08T10:10:36.620000Z"}
  {"type":"done","side":"buy","order_id":"bc13bb30-cc91-45ee-a9a9-8bcd07fb7eec","reason":"canceled","product_id":"ETH-USD","price":"224.98000000","remaining_size":"35.25000000","sequence":7147163755,"time":"2019-08-08T10:10:36.621000Z"}
  {"type":"done","side":"buy","order_id":"c247911a-31a2-4fe2-b8a7-1b3da37615e8","reason":"canceled","product_id":"ETH-USD","price":"225.06000000","remaining_size":"2.00000000","sequence":7147163756,"time":"2019-08-08T10:10:36.621000Z"}
  {"type":"received","order_id":"ded2e129-3200-40c7-81f8-5b2eaa7cca6f","order_type":"limit","size":"2.01796475","price":"225.18000000","side":"buy","client_oid":"00000003-0000-0000-0000-000000872838","product_id":"ETH-USD","sequence":7147163757,"time":"2019-08-08T10:10:36.622000Z"}
  {"type":"open","side":"buy","price":"225.18000000","order_id":"ded2e129-3200-40c7-81f8-5b2eaa7cca6f","remaining_size":"2.01796475","product_id":"ETH-USD","sequence":7147163758,"time":"2019-08-08T10:10:36.622000Z"}
  {"type":"done","side":"sell","order_id":"a032c6bf-ce02-49a6-ae28-e0b24b69e2ee","reason":"canceled","product_id":"ETH-USD","price":"225.32000000","remaining_size":"35.22200000","sequence":7147163759,"time":"2019-08-08T10:10:36.622000Z"}
  {"type":"done","side":"buy","order_id":"4874fd07-68b1-401a-bcec-7bcbbd9e62ac","reason":"canceled","product_id":"BTC-USD","price":"11802.86000000","remaining_size":"0.04814580","sequence":10477650092,"time":"2019-08-08T10:10:36.622000Z"}
  {"type":"received","order_id":"477aafb2-bf0a-46ee-baf5-00ec9f068606","order_type":"limit","size":"35.34100000","price":"224.96000000","side":"buy","client_oid":"a1e552a4-d41c-4846-9e21-850699506959","product_id":"ETH-USD","sequence":7147163760,"time":"2019-08-08T10:10:36.627000Z"}
  {"type":"open","side":"buy","price":"224.96000000","order_id":"477aafb2-bf0a-46ee-baf5-00ec9f068606","remaining_size":"35.34100000","product_id":"ETH-USD","sequence":7147163761,"time":"2019-08-08T10:10:36.627000Z"}
  {"type":"received","order_id":"77391958-1fe8-49d9-8ea6-279c789f2cc6","order_type":"limit","size":"35.48700000","price":"225.31000000","side":"sell","client_oid":"6df0e13a-00d5-40f6-b1d2-a03a0b07e39e","product_id":"ETH-USD","sequence":7147163762,"time":"2019-08-08T10:10:36.637000Z"}
  {"type":"open","side":"sell","price":"225.31000000","order_id":"77391958-1fe8-49d9-8ea6-279c789f2cc6","remaining_size":"35.48700000","product_id":"ETH-USD","sequence":7147163763,"time":"2019-08-08T10:10:36.637000Z"}
  {"type":"done","side":"buy","order_id":"d8010d35-633b-4a8d-8866-efb8175ee056","reason":"canceled","product_id":"ETH-USD","price":"225.17000000","remaining_size":"2.53000000","sequence":7147163764,"time":"2019-08-08T10:10:36.637000Z"}
  {"type":"received","order_id":"af6b877e-ae12-43f4-8f2a-d4bb48ecbfd9","order_type":"limit","size":"0.05836500","price":"11803.38000000","side":"buy","client_oid":"e95ed584-4653-4c98-a679-fca45cacf78d","product_id":"BTC-USD","sequence":10477650093,"time":"2019-08-08T10:10:36.636000Z"}
  {"type":"open","side":"buy","price":"11803.38000000","order_id":"af6b877e-ae12-43f4-8f2a-d4bb48ecbfd9","remaining_size":"0.05836500","product_id":"BTC-USD","sequence":10477650094,"time":"2019-08-08T10:10:36.636000Z"}
  {"type":"received","order_id":"3af46f4e-108e-4f73-a2e2-46ba47d916f8","order_type":"limit","size":"2.29000000","price":"225.19000000","side":"buy","client_oid":"5cb4ce93-79dd-4a1b-85c3-6c14c91acb5b","product_id":"ETH-USD","sequence":7147163765,"time":"2019-08-08T10:10:36.671000Z"}
  {"type":"open","side":"buy","price":"225.19000000","order_id":"3af46f4e-108e-4f73-a2e2-46ba47d916f8","remaining_size":"2.29000000","product_id":"ETH-USD","sequence":7147163766,"time":"2019-08-08T10:10:36.671000Z"}
  {"type":"received","order_id":"90471e3a-5ef8-489e-872a-a3f307b8b21e","order_type":"limit","size":"0.01000000","price":"11792.54000000","side":"buy","client_oid":"fe825b75-1fee-45bf-87f1-e0bebe35fedd","product_id":"BTC-USD","sequence":10477650095,"time":"2019-08-08T10:10:36.676000Z"}
  {"type":"open","side":"buy","price":"11792.54000000","order_id":"90471e3a-5ef8-489e-872a-a3f307b8b21e","remaining_size":"0.01000000","product_id":"BTC-USD","sequence":10477650096,"time":"2019-08-08T10:10:36.676000Z"}
  {"type":"done","side":"buy","order_id":"af6b877e-ae12-43f4-8f2a-d4bb48ecbfd9","reason":"canceled","product_id":"BTC-USD","price":"11803.38000000","remaining_size":"0.05836500","sequence":10477650097,"time":"2019-08-08T10:10:36.677000Z"}
  {"type":"done","side":"buy","order_id":"dc8a59ac-79bc-4862-bf14-55ac2a89f5ec","reason":"canceled","product_id":"ETH-USD","price":"225.17000000","remaining_size":"10.00000000","sequence":7147163767,"time":"2019-08-08T10:10:36.684000Z"}
  {"type":"done","side":"sell","order_id":"d9080d7e-b67d-4974-8bb3-aa07d4fc03a9","reason":"canceled","product_id":"ETH-USD","price":"225.20000000","remaining_size":"2.23995439","sequence":7147163768,"time":"2019-08-08T10:10:36.735000Z"}
  {"type":"received","order_id":"2b607fbe-03c4-4070-b55b-22900638ef14","order_type":"limit","size":"0.15600000","price":"11801.48000000","side":"buy","client_oid":"","product_id":"BTC-USD","sequence":10477650098,"time":"2019-08-08T10:10:36.746000Z"}
  {"type":"open","side":"buy","price":"11801.48000000","order_id":"2b607fbe-03c4-4070-b55b-22900638ef14","remaining_size":"0.15600000","product_id":"BTC-USD","sequence":10477650099,"time":"2019-08-08T10:10:36.746000Z"}
  {"type":"received","order_id":"25c81748-f928-475c-9674-360c449df222","order_type":"limit","size":"2.00000000","price":"225.06000000","side":"buy","client_oid":"cc8fbcd3-eb2b-47c8-bc32-abb1c1a544c9","product_id":"ETH-USD","sequence":7147163769,"time":"2019-08-08T10:10:36.783000Z"}
  {"type":"open","side":"buy","price":"225.06000000","order_id":"25c81748-f928-475c-9674-360c449df222","remaining_size":"2.00000000","product_id":"ETH-USD","sequence":7147163770,"time":"2019-08-08T10:10:36.783000Z"}
  {"type":"done","side":"sell","order_id":"d1ddd0e2-a94b-4816-973c-a9ab8395b94d","reason":"canceled","product_id":"ETH-USD","price":"225.27000000","remaining_size":"2.42595380","sequence":7147163771,"time":"2019-08-08T10:10:36.788000Z"}
  {"type":"done","side":"buy","order_id":"5e8a9035-4649-456b-a0ad-36fb114fe0af","reason":"canceled","product_id":"ETH-USD","price":"225.06000000","remaining_size":"0.82176327","sequence":7147163772,"time":"2019-08-08T10:10:36.792000Z"}
  {"type":"done","side":"sell","order_id":"09648818-5123-4fc3-b209-60657e75ca37","reason":"canceled","product_id":"BTC-USD","price":"11872.87000000","remaining_size":"0.01000000","sequence":10477650100,"time":"2019-08-08T10:10:36.792000Z"}
  {"type":"received","order_id":"4d996abf-7eaf-4eab-aa02-4028856c4d08","order_type":"limit","size":"2.01796475","price":"225.29000000","side":"sell","client_oid":"00000004-0000-0000-0000-000000872673","product_id":"ETH-USD","sequence":7147163773,"time":"2019-08-08T10:10:36.794000Z"}
  {"type":"open","side":"sell","price":"225.29000000","order_id":"4d996abf-7eaf-4eab-aa02-4028856c4d08","remaining_size":"2.01796475","product_id":"ETH-USD","sequence":7147163774,"time":"2019-08-08T10:10:36.794000Z"}
  {"type":"received","order_id":"56e93f2f-c5f5-45c4-af90-7b4f01342e46","order_type":"limit","size":"0.82161730","price":"225.05000000","side":"buy","client_oid":"00000006-6347-3221-2191-553657328442","product_id":"ETH-USD","sequence":7147163775,"time":"2019-08-08T10:10:36.796000Z"}
  {"type":"open","side":"buy","price":"225.05000000","order_id":"56e93f2f-c5f5-45c4-af90-7b4f01342e46","remaining_size":"0.82161730","product_id":"ETH-USD","sequence":7147163776,"time":"2019-08-08T10:10:36.796000Z"}
  {"type":"received","order_id":"204359d0-171d-4c49-a681-7637e696adfe","order_type":"limit","size":"10.00000000","price":"225.20000000","side":"sell","client_oid":"bd1605b1-40d4-4594-bb1f-70a9df568fe4","product_id":"ETH-USD","sequence":7147163777,"time":"2019-08-08T10:10:36.817000Z"}
  {"type":"open","side":"sell","price":"225.20000000","order_id":"204359d0-171d-4c49-a681-7637e696adfe","remaining_size":"10.00000000","product_id":"ETH-USD","sequence":7147163778,"time":"2019-08-08T10:10:36.817000Z"}
  {"type":"received","order_id":"d676b7d2-ebc0-478f-93f4-fb63a2d4afc8","order_type":"limit","size":"0.00100796","price":"12448.28000000","side":"sell","client_oid":"","product_id":"BTC-USD","sequence":10477650101,"time":"2019-08-08T10:10:36.850000Z"}
  {"type":"open","side":"sell","price":"12448.28000000","order_id":"d676b7d2-ebc0-478f-93f4-fb63a2d4afc8","remaining_size":"0.00100796","product_id":"BTC-USD","sequence":10477650102,"time":"2019-08-08T10:10:36.850000Z"}
  {"type":"done","side":"sell","order_id":"a8a0b400-e081-4b4e-ab7e-d62bb5c0f5cc","reason":"canceled","product_id":"BTC-USD","price":"11875.28000000","remaining_size":"0.01971910","sequence":10477650103,"time":"2019-08-08T10:10:36.850000Z"}
  {"type":"received","order_id":"9c6748e4-a23c-4dfb-a736-23cd279413f3","order_type":"limit","size":"0.00100831","price":"12069.78000000","side":"sell","client_oid":"","product_id":"BTC-USD","sequence":10477650104,"time":"2019-08-08T10:10:36.876000Z"}
  {"type":"open","side":"sell","price":"12069.78000000","order_id":"9c6748e4-a23c-4dfb-a736-23cd279413f3","remaining_size":"0.00100831","product_id":"BTC-USD","sequence":10477650105,"time":"2019-08-08T10:10:36.876000Z"}
  {"type":"heartbeat","last_trade_id":0,"product_id":"BTC-USD","sequence":10477650105,"time":"2019-08-08T10:10:36.933402Z"}
  {"type":"heartbeat","last_trade_id":0,"product_id":"ETH-USD","sequence":7147163778,"time":"2019-08-08T10:10:36.953459Z"}
  {"type":"done","side":"buy","order_id":"90471e3a-5ef8-489e-872a-a3f307b8b21e","reason":"canceled","product_id":"BTC-USD","price":"11792.54000000","remaining_size":"0.01000000","sequence":10477650106,"time":"2019-08-08T10:10:36.951000Z"}
  {"type":"done","side":"buy","order_id":"b3b40d92-b8af-43d4-b32d-065ce26b52d0","reason":"canceled","product_id":"ETH-USD","price":"220.50000000","remaining_size":"0.29800000","sequence":7147163779,"time":"2019-08-08T10:10:36.981000Z"}
  {"type":"received","order_id":"ce962b96-2b6f-4703-8a21-ea6da556f292","order_type":"limit","size":"0.18743750","price":"11868.89000000","side":"sell","client_oid":"a5b76dbb-f6f5-4ad9-b6a3-e7a3fc2d6c33","product_id":"BTC-USD","sequence":10477650107,"time":"2019-08-08T10:10:36.990000Z"}
  {"type":"open","side":"sell","price":"11868.89000000","order_id":"ce962b96-2b6f-4703-8a21-ea6da556f292","remaining_size":"0.18743750","product_id":"BTC-USD","sequence":10477650108,"time":"2019-08-08T10:10:36.990000Z"}
  {"type":"done","side":"sell","order_id":"fa2e2257-255e-4678-b769-7911e1114efe","reason":"canceled","product_id":"BTC-USD","price":"11844.34000000","remaining_size":"2.10600000","sequence":10477650109,"time":"2019-08-08T10:10:37.200000Z"}
  {"type":"received","order_id":"58433c07-955a-498c-a3da-f96d88c518e9","order_type":"limit","size":"2.11100000","price":"11842.44000000","side":"sell","client_oid":"1a0eb47b-5ba5-4301-bc95-b8ae958f4b05","product_id":"BTC-USD","sequence":10477650110,"time":"2019-08-08T10:10:37.700000Z"}
  {"type":"open","side":"sell","price":"11842.44000000","order_id":"58433c07-955a-498c-a3da-f96d88c518e9","remaining_size":"2.11100000","product_id":"BTC-USD","sequence":10477650111,"time":"2019-08-08T10:10:37.700000Z"}
  {"type":"done","side":"buy","order_id":"aa0a903f-6780-4c49-865e-bd42c114aa0b","reason":"canceled","product_id":"BTC-USD","price":"11811.17000000","remaining_size":"0.90400000","sequence":10477650112,"time":"2019-08-08T10:10:37.700000Z"}
  {"type":"received","order_id":"211c8fe6-fba2-4e18-bab3-14c7a8b72ee0","order_type":"limit","size":"0.06756000","price":"11792.89000000","side":"buy","client_oid":"5a24ce8e-84b2-482c-8a2a-fdf88113ee1a","product_id":"BTC-USD","sequence":10477650113,"time":"2019-08-08T10:10:37.190000Z"}
  {"type":"open","side":"buy","price":"11792.89000000","order_id":"211c8fe6-fba2-4e18-bab3-14c7a8b72ee0","remaining_size":"0.06756000","product_id":"BTC-USD","sequence":10477650114,"time":"2019-08-08T10:10:37.190000Z"}
  {"type":"received","order_id":"b9527bd9-256d-44c9-ba85-bc15a878bbd1","order_type":"limit","size":"0.01000000","price":"11871.77000000","side":"sell","client_oid":"f8717f79-9736-4abf-ac54-5423b7e7b772","product_id":"BTC-USD","sequence":10477650115,"time":"2019-08-08T10:10:37.310000Z"}
  {"type":"open","side":"sell","price":"11871.77000000","order_id":"b9527bd9-256d-44c9-ba85-bc15a878bbd1","remaining_size":"0.01000000","product_id":"BTC-USD","sequence":10477650116,"time":"2019-08-08T10:10:37.310000Z"}
  {"type":"done","side":"sell","order_id":"b9527bd9-256d-44c9-ba85-bc15a878bbd1","reason":"canceled","product_id":"BTC-USD","price":"11871.77000000","remaining_size":"0.01000000","
